Workbook

Sheet Test Shipments
A1: FlexiTog EU: quick quote for MENA and Türkiye
A2: FlexiTog EU B.V. (Helmond, NL, part of RefrigiWear Group) is selecting logistics partners for cold-store workwear shipments to Saudi Arabia, UAE, Kuwait, Qatar, Türkiye, Morocco, Algeria, Egypt and Tunisia. Estimated 140 to 330 shipments per year, about three quarters to the GCC. Estimates only, not a volume commitment.
A4: FlexiTog contact | D4: Sami El Hassouni, Logistics Engineering | L4: Input check
A5: E-mail | D5: [fill in before sending] | L5: =IF(COUNTIF(R19:R51,"OK")+COUNTIF(R19:R51,"Not offered")=33,"No problems found",33-COUNTIF(R19:R51,"OK")-COUNTIF(R19:R51,"Not offered")&" rows to check, see column R") -> No problems found
A6: Please reply by | D6: [fill in before sending]
A7: Time needed | D7: Option 1: about 45 to 60 minutes. Options 2 and 3: about 30 minutes extra, only if you offer them
A9: How to fill in: three ways to deliver the same shipment
A10: Option 1 (required): you collect in Helmond and deliver to the consignee door. Freight forwarding or express.
A11: Option 2 (optional): FlexiTog stock in your regional warehouse. Price the delivery from your warehouse to the door here, and your warehouse rates on the Warehouse sheet.
A12: Option 3 (optional): any other service you advise, for example road, sea, economy air or consolidation.
A13: Every price is all-in DAP to the door in EUR excl. VAT, including fuel and every fixed fee. Not included: import duty, import VAT and import clearance fees (paid by the consignee).
A14: Leave a price blank for a service you do not offer. Use your own volumetric rule. Cartons are 60 x 40 x 40 cm, non-dangerous workwear, stackable. Paste values only, not formulas.
I16: Option 1: from Helmond (required) | L16: Option 2: from your warehouse (optional) | N16: Option 3: other option you offer (optional)
A17: ID | B17: Lane | C17: Destination | D17: Delivery city | E17: Size | F17: Gross kg | G17: Cartons | H17: Volume m3 | I17: Service | J17: All-in price EUR | K17: Transit days | L17: Delivery price EUR | M17: Transit days | N17: Service | O17: All-in price EUR | P17: Transit days | Q17: Comment (optional) | R17: Check
A18: EX | B18: Example | C18: Netherlands | D18: Rotterdam | E18: S | F18: 8 | G18: 1 | H18: 0.096 | I18: Express parcel | J18: 25 | K18: 1 | L18: 14 | M18: 1 | N18: Road economy | O18: 18 | P18: 2 | Q18: Fuel 30% included, Nov 2026 | R18: OK
A19: T01 | B19: L01 | C19: Saudi Arabia | D19: Jeddah | E19: S | F19: 8 | G19: 1 | H19: 0.096 | R19: =IF(OR(AND(J19<>"",NOT(ISNUMBER(J19))),AND(K19<>"",NOT(ISNUMBER(K19))),AND(L19<>"",NOT(ISNUMBER(L19))),AND(M19<>"",NOT(ISNUMBER(M19))),AND(O19<>"",NOT(ISNUMBER(O19))),AND(P19<>"",NOT(ISNUMBER(P19)))),"Number needed",IF(AND(I19="",J19="",K19=""),"Not offered",IF(J19="","Price missing",IF(K19="","Transit days missing",IF(AND(L19<>"",M19=""),"Option 2 transit days missing",IF(AND(O19<>"",P19=""),"Option 3 transit days missing","OK")))))) -> Not offered
A20: T02 | B20: L01 | C20: Saudi Arabia | D20: Jeddah | E20: M | F20: 52 | G20: 4 | H20: 0.384 | R20: =IF(OR(AND(J20<>"",NOT(ISNUMBER(J20))),AND(K20<>"",NOT(ISNUMBER(K20))),AND(L20<>"",NOT(ISNUMBER(L20))),AND(M20<>"",NOT(ISNUMBER(M20))),AND(O20<>"",NOT(ISNUMBER(O20))),AND(P20<>"",NOT(ISNUMBER(P20)))),"Number needed",IF(AND(I20="",J20="",K20=""),"Not offered",IF(J20="","Price missing",IF(K20="","Transit days missing",IF(AND(L20<>"",M20=""),"Option 2 transit days missing",IF(AND(O20<>"",P20=""),"Option 3 transit days missing","OK")))))) -> Not offered
A21: T03 | B21: L01 | C21: Saudi Arabia | D21: Jeddah | E21: L | F21: 261 | G21: 18 | H21: 1.728 | R21: =IF(OR(AND(J21<>"",NOT(ISNUMBER(J21))),AND(K21<>"",NOT(ISNUMBER(K21))),AND(L21<>"",NOT(ISNUMBER(L21))),AND(M21<>"",NOT(ISNUMBER(M21))),AND(O21<>"",NOT(ISNUMBER(O21))),AND(P21<>"",NOT(ISNUMBER(P21)))),"Number needed",IF(AND(I21="",J21="",K21=""),"Not offered",IF(J21="","Price missing",IF(K21="","Transit days missing",IF(AND(L21<>"",M21=""),"Option 2 transit days missing",IF(AND(O21<>"",P21=""),"Option 3 transit days missing","OK")))))) -> Not offered
A22: T04 | B22: L01 | C22: Saudi Arabia | D22: Jeddah | E22: XL | F22: 941 | G22: 64 | H22: 6.144 | R22: =IF(OR(AND(J22<>"",NOT(ISNUMBER(J22))),AND(K22<>"",NOT(ISNUMBER(K22))),AND(L22<>"",NOT(ISNUMBER(L22))),AND(M22<>"",NOT(ISNUMBER(M22))),AND(O22<>"",NOT(ISNUMBER(O22))),AND(P22<>"",NOT(ISNUMBER(P22)))),"Number needed",IF(AND(I22="",J22="",K22=""),"Not offered",IF(J22="","Price missing",IF(K22="","Transit days missing",IF(AND(L22<>"",M22=""),"Option 2 transit days missing",IF(AND(O22<>"",P22=""),"Option 3 transit days missing","OK")))))) -> Not offered
A23: T05 | B23: L01 | C23: Saudi Arabia | D23: Jeddah | E23: XXL | F23: 2380 | G23: 160 | H23: 15.36 | R23: =IF(OR(AND(J23<>"",NOT(ISNUMBER(J23))),AND(K23<>"",NOT(ISNUMBER(K23))),AND(L23<>"",NOT(ISNUMBER(L23))),AND(M23<>"",NOT(ISNUMBER(M23))),AND(O23<>"",NOT(ISNUMBER(O23))),AND(P23<>"",NOT(ISNUMBER(P23)))),"Number needed",IF(AND(I23="",J23="",K23=""),"Not offered",IF(J23="","Price missing",IF(K23="","Transit days missing",IF(AND(L23<>"",M23=""),"Option 2 transit days missing",IF(AND(O23<>"",P23=""),"Option 3 transit days missing","OK")))))) -> Not offered
A24: T06 | B24: L02 | C24: United Arab Emirates | D24: Dubai | E24: S | F24: 8 | G24: 1 | H24: 0.096 | R24: =IF(OR(AND(J24<>"",NOT(ISNUMBER(J24))),AND(K24<>"",NOT(ISNUMBER(K24))),AND(L24<>"",NOT(ISNUMBER(L24))),AND(M24<>"",NOT(ISNUMBER(M24))),AND(O24<>"",NOT(ISNUMBER(O24))),AND(P24<>"",NOT(ISNUMBER(P24)))),"Number needed",IF(AND(I24="",J24="",K24=""),"Not offered",IF(J24="","Price missing",IF(K24="","Transit days missing",IF(AND(L24<>"",M24=""),"Option 2 transit days missing",IF(AND(O24<>"",P24=""),"Option 3 transit days missing","OK")))))) -> Not offered
A25: T07 | B25: L02 | C25: United Arab Emirates | D25: Dubai | E25: M | F25: 52 | G25: 4 | H25: 0.384 | R25: =IF(OR(AND(J25<>"",NOT(ISNUMBER(J25))),AND(K25<>"",NOT(ISNUMBER(K25))),AND(L25<>"",NOT(ISNUMBER(L25))),AND(M25<>"",NOT(ISNUMBER(M25))),AND(O25<>"",NOT(ISNUMBER(O25))),AND(P25<>"",NOT(ISNUMBER(P25)))),"Number needed",IF(AND(I25="",J25="",K25=""),"Not offered",IF(J25="","Price missing",IF(K25="","Transit days missing",IF(AND(L25<>"",M25=""),"Option 2 transit days missing",IF(AND(O25<>"",P25=""),"Option 3 transit days missing","OK")))))) -> Not offered
A26: T08 | B26: L02 | C26: United Arab Emirates | D26: Dubai | E26: L | F26: 261 | G26: 18 | H26: 1.728 | R26: =IF(OR(AND(J26<>"",NOT(ISNUMBER(J26))),AND(K26<>"",NOT(ISNUMBER(K26))),AND(L26<>"",NOT(ISNUMBER(L26))),AND(M26<>"",NOT(ISNUMBER(M26))),AND(O26<>"",NOT(ISNUMBER(O26))),AND(P26<>"",NOT(ISNUMBER(P26)))),"Number needed",IF(AND(I26="",J26="",K26=""),"Not offered",IF(J26="","Price missing",IF(K26="","Transit days missing",IF(AND(L26<>"",M26=""),"Option 2 transit days missing",IF(AND(O26<>"",P26=""),"Option 3 transit days missing","OK")))))) -> Not offered
A27: T09 | B27: L03 | C27: Kuwait | D27: Kuwait City | E27: S | F27: 8 | G27: 1 | H27: 0.096 | R27: =IF(OR(AND(J27<>"",NOT(ISNUMBER(J27))),AND(K27<>"",NOT(ISNUMBER(K27))),AND(L27<>"",NOT(ISNUMBER(L27))),AND(M27<>"",NOT(ISNUMBER(M27))),AND(O27<>"",NOT(ISNUMBER(O27))),AND(P27<>"",NOT(ISNUMBER(P27)))),"Number needed",IF(AND(I27="",J27="",K27=""),"Not offered",IF(J27="","Price missing",IF(K27="","Transit days missing",IF(AND(L27<>"",M27=""),"Option 2 transit days missing",IF(AND(O27<>"",P27=""),"Option 3 transit days missing","OK")))))) -> Not offered
A28: T10 | B28: L03 | C28: Kuwait | D28: Kuwait City | E28: M | F28: 52 | G28: 4 | H28: 0.384 | R28: =IF(OR(AND(J28<>"",NOT(ISNUMBER(J28))),AND(K28<>"",NOT(ISNUMBER(K28))),AND(L28<>"",NOT(ISNUMBER(L28))),AND(M28<>"",NOT(ISNUMBER(M28))),AND(O28<>"",NOT(ISNUMBER(O28))),AND(P28<>"",NOT(ISNUMBER(P28)))),"Number needed",IF(AND(I28="",J28="",K28=""),"Not offered",IF(J28="","Price missing",IF(K28="","Transit days missing",IF(AND(L28<>"",M28=""),"Option 2 transit days missing",IF(AND(O28<>"",P28=""),"Option 3 transit days missing","OK")))))) -> Not offered
A29: T11 | B29: L03 | C29: Kuwait | D29: Kuwait City | E29: L | F29: 261 | G29: 18 | H29: 1.728 | R29: =IF(OR(AND(J29<>"",NOT(ISNUMBER(J29))),AND(K29<>"",NOT(ISNUMBER(K29))),AND(L29<>"",NOT(ISNUMBER(L29))),AND(M29<>"",NOT(ISNUMBER(M29))),AND(O29<>"",NOT(ISNUMBER(O29))),AND(P29<>"",NOT(ISNUMBER(P29)))),"Number needed",IF(AND(I29="",J29="",K29=""),"Not offered",IF(J29="","Price missing",IF(K29="","Transit days missing",IF(AND(L29<>"",M29=""),"Option 2 transit days missing",IF(AND(O29<>"",P29=""),"Option 3 transit days missing","OK")))))) -> Not offered
A30: T12 | B30: L03 | C30: Kuwait | D30: Kuwait City | E30: XL | F30: 941 | G30: 64 | H30: 6.144 | R30: =IF(OR(AND(J30<>"",NOT(ISNUMBER(J30))),AND(K30<>"",NOT(ISNUMBER(K30))),AND(L30<>"",NOT(ISNUMBER(L30))),AND(M30<>"",NOT(ISNUMBER(M30))),AND(O30<>"",NOT(ISNUMBER(O30))),AND(P30<>"",NOT(ISNUMBER(P30)))),"Number needed",IF(AND(I30="",J30="",K30=""),"Not offered",IF(J30="","Price missing",IF(K30="","Transit days missing",IF(AND(L30<>"",M30=""),"Option 2 transit days missing",IF(AND(O30<>"",P30=""),"Option 3 transit days missing","OK")))))) -> Not offered
... A51: T33 | B51: L09 | C51: Tunisia | D51: Sousse | E51: L | F51: 261 | G51: 18 | H51: 1.728 | R51: =IF(OR(AND(J51<>"",NOT(ISNUMBER(J51))),AND(K51<>"",NOT(ISNUMBER(K51))),AND(L51<>"",NOT(ISNUMBER(L51))),AND(M51<>"",NOT(ISNUMBER(M51))),AND(O51<>"",NOT(ISNUMBER(O51))),AND(P51<>"",NOT(ISNUMBER(P51)))),"Number needed",IF(AND(I51="",J51="",K51=""),"Not offered",IF(J51="","Price missing",IF(K51="","Transit days missing",IF(AND(L51<>"",M51=""),"Option 2 transit days missing",IF(AND(O51<>"",P51=""),"Option 3 transit days missing","OK")))))) -> Not offered
A53: Sizes: S = parcel, M = small air shipment, L = about 1 pallet, XL = about 4 pallets, XXL = about 10 pallets. Example shipments for pricing only, not a volume commitment.

Sheet Questions
A1: Questions: service level, quality and options
A2: Choose from the dropdown where one is shown. Add context in Comment.
A4: # | B4: Question | C4: Your answer | D4: Comment (optional)
A5: A. Contact, validity and commercial
A6: Q01 | B6: Company name
A7: Q02 | B7: Contact person for this quote
A8: Q03 | B8: Contact e-mail
A9: Q04 | B9: Contact phone (with country code)
A10: Q05 | B10: Prices valid until
A11: Q06 | B11: Fuel surcharge % included in your prices (state the month in Comment)
A12: Q07 | B12: Surcharges possible on top of the all-in prices (peak, emergency, oversize, remote area)
A13: Q08 | B13: Payment terms (days after invoice date)
A14: B. Service level
A15: Q09 | B15: Daily pick-up cut-off time in Helmond for same-day dispatch
A16: Q10 | B16: Next-day delivery in the GCC (Saudi Arabia, UAE, Kuwait, Qatar)
A17: Q11 | B17: Average import clearance time at destination (working days)
A18: Q12 | B18: Capacity in the peak month (1.5 times an average month)
A19: C. Quality
A20: Q13 | B20: On-time delivery rate on these lanes, last 12 months
A21: Q14 | B21: Damage and loss rate, last 12 months (share of shipments)
A22: Q15 | B22: Track and trace and electronic proof of delivery (e-POD)
A23: Q16 | B23: One contact person and one invoice for all lanes
A24: Q17 | B24: Experience with Saudi SASO / SABER for textiles and footwear
A25: Q18 | B25: Handling of Egypt ACID / CargoX pre-registration
A26: Q19 | B26: Certifications held
A27: D. Options available (list countries in Comment where not all 9)
A28: Q20 | B28: Express parcel service
A29: Q21 | B29: Air freight
A30: Q22 | B30: Road groupage (for example Türkiye, Morocco, Tunisia)
A31: Q23 | B31: Sea freight LCL or FCL
A32: Q24 | B32: Import customs clearance for the consignee (on their account)
A33: Q25 | B33: DDP service (you pay import duty and VAT, recharged to FlexiTog)
A34: Q26 | B34: You issue EUR.1 / A.TR origin documents
A35: Q27 | B35: Cargo insurance premium (% of invoice value). Leave blank if not offered
A36: Q28 | B36: Your standard rate sheets and surcharge list are attached

Sheet Warehouse
A1: Option 2: FlexiTog stock in your regional warehouse
A2: Only if you offer stock-holding. FlexiTog sends stock from Helmond or directly from suppliers. You store, pick, pack and deliver. Delivery prices go in Option 2 on the Test Shipments sheet.
A4: # | B4: Question | C4: Your answer | D4: Comment (optional)
A5: A. Location
A6: W01 | B6: Warehouse location (city, country)
A7: W02 | B7: Customs status of the stock
A8: W03 | B8: Countries you deliver to from this warehouse
A9: B. Warehouse rates (EUR excl. VAT). Pallet: 120 x 80 cm, max. 160 cm high, about 250 kg of cartons
A10: W04 | B10: Storage per pallet position per month
A11: W05 | B11: Inbound receiving per pallet (from Helmond or a supplier)
A12: W06 | B12: Pick per order line
A13: W07 | B13: Pack and dispatch per order (labels, documents)
A14: W08 | B14: Export or clearance fee per outbound order, if not in the delivery prices
A15: W09 | B15: Fixed monthly fee (account, WMS, minimum charge)
A16: W10 | B16: Minimum contract period (months)
A17: C. Replenishment: Helmond to your warehouse (all-in, per pallet)
A18: W11 | B18: Price per pallet by sea
A19: W12 | B19: Transit days by sea (working days)
A20: W13 | B20: Price per pallet by air
A21: W14 | B21: Transit days by air (working days)

Sheet Export
A1: key | B1: value | C1: type | D1: description
A2: meta.rfq_version | B2: RFQ-MENA-TR-QUICK v2.3 | C2: text | D2: Template version
A3: meta.shipment_count | B3: 33 | C3: number | D3: Number of test shipments
A4: meta.input_check | B4: ='Test Shipments'!L5 -> No problems found | C4: text | D4: Result of the in-file input check
A5: wh.W01.answer | B5: =IF(Warehouse!C6="","",Warehouse!C6) | C5: text | D5: Warehouse location (city, country)
A6: wh.W01.comment | B6: =IF(Warehouse!D6="","",Warehouse!D6) | C6: text | D6: Warehouse location (city, country) (comment)
A7: wh.W02.answer | B7: =IF(Warehouse!C7="","",Warehouse!C7) | C7: list | D7: Customs status of the stock
A8: wh.W02.comment | B8: =IF(Warehouse!D7="","",Warehouse!D7) | C8: text | D8: Customs status of the stock (comment)
A9: wh.W03.answer | B9: =IF(Warehouse!C8="","",Warehouse!C8) | C9: list | D9: Countries you deliver to from this warehouse
A10: wh.W03.comment | B10: =IF(Warehouse!D8="","",Warehouse!D8) | C10: text | D10: Countries you deliver to from this warehouse (comment)
A11: wh.W04.answer | B11: =IF(Warehouse!C10="","",Warehouse!C10) | C11: number | D11: Storage per pallet position per month
A12: wh.W04.comment | B12: =IF(Warehouse!D10="","",Warehouse!D10) | C12: text | D12: Storage per pallet position per month (comment)
A13: wh.W05.answer | B13: =IF(Warehouse!C11="","",Warehouse!C11) | C13: number | D13: Inbound receiving per pallet (from Helmond or a supplier)
A14: wh.W05.comment | B14: =IF(Warehouse!D11="","",Warehouse!D11) | C14: text | D14: Inbound receiving per pallet (from Helmond or a supplier) (comment)
A15: wh.W06.answer | B15: =IF(Warehouse!C12="","",Warehouse!C12) | C15: number | D15: Pick per order line
A16: wh.W06.comment | B16: =IF(Warehouse!D12="","",Warehouse!D12) | C16: text | D16: Pick per order line (comment)
A17: wh.W07.answer | B17: =IF(Warehouse!C13="","",Warehouse!C13) | C17: number | D17: Pack and dispatch per order (labels, documents)
A18: wh.W07.comment | B18: =IF(Warehouse!D13="","",Warehouse!D13) | C18: text | D18: Pack and dispatch per order (labels, documents) (comment)
A19: wh.W08.answer | B19: =IF(Warehouse!C14="","",Warehouse!C14) | C19: number | D19: Export or clearance fee per outbound order, if not in the delivery prices
A20: wh.W08.comment | B20: =IF(Warehouse!D14="","",Warehouse!D14) | C20: text | D20: Export or clearance fee per outbound order, if not in the delivery prices (comment)
A21: wh.W09.answer | B21: =IF(Warehouse!C15="","",Warehouse!C15) | C21: number | D21: Fixed monthly fee (account, WMS, minimum charge)
A22: wh.W09.comment | B22: =IF(Warehouse!D15="","",Warehouse!D15) | C22: text | D22: Fixed monthly fee (account, WMS, minimum charge) (comment)
A23: wh.W10.answer | B23: =IF(Warehouse!C16="","",Warehouse!C16) | C23: number | D23: Minimum contract period (months)
A24: wh.W10.comment | B24: =IF(Warehouse!D16="","",Warehouse!D16) | C24: text | D24: Minimum contract period (months) (comment)
A25: wh.W11.answer | B25: =IF(Warehouse!C18="","",Warehouse!C18) | C25: number | D25: Price per pallet by sea
A26: wh.W11.comment | B26: =IF(Warehouse!D18="","",Warehouse!D18) | C26: text | D26: Price per pallet by sea (comment)
A27: wh.W12.answer | B27: =IF(Warehouse!C19="","",Warehouse!C19) | C27: number | D27: Transit days by sea (working days)
A28: wh.W12.comment | B28: =IF(Warehouse!D19="","",Warehouse!D19) | C28: text | D28: Transit days by sea (working days) (comment)
A29: wh.W13.answer | B29: =IF(Warehouse!C20="","",Warehouse!C20) | C29: number | D29: Price per pallet by air
A30: wh.W13.comment | B30: =IF(Warehouse!D20="","",Warehouse!D20) | C30: text | D30: Price per pallet by air (comment)
A31: wh.W14.answer | B31: =IF(Warehouse!C21="","",Warehouse!C21) | C31: number | D31: Transit days by air (working days)
A32: wh.W14.comment | B32: =IF(Warehouse!D21="","",Warehouse!D21) | C32: text | D32: Transit days by air (working days) (comment)
A33: q.Q01.answer | B33: =IF(Questions!C6="","",Questions!C6) | C33: text | D33: Company name
A34: q.Q01.comment | B34: =IF(Questions!D6="","",Questions!D6) | C34: text | D34: Company name (comment)
A35: q.Q02.answer | B35: =IF(Questions!C7="","",Questions!C7) | C35: text | D35: Contact person for this quote
A36: q.Q02.comment | B36: =IF(Questions!D7="","",Questions!D7) | C36: text | D36: Contact person for this quote (comment)
A37: q.Q03.answer | B37: =IF(Questions!C8="","",Questions!C8) | C37: text | D37: Contact e-mail
A38: q.Q03.comment | B38: =IF(Questions!D8="","",Questions!D8) | C38: text | D38: Contact e-mail (comment)
A39: q.Q04.answer | B39: =IF(Questions!C9="","",Questions!C9) | C39: text | D39: Contact phone (with country code)
A40: q.Q04.comment | B40: =IF(Questions!D9="","",Questions!D9) | C40: text | D40: Contact phone (with country code) (comment)
...
