Workbook
Name LR_Lane: 'Timeline Rules'!$A$6:$A$14
Name LR_Code: 'Timeline Rules'!$D$6:$D$14
Name LR_Target: 'Timeline Rules'!$E$6:$E$14
Name DH_Table: 'Timeline Rules'!$A$41:$I$57
Name DH_Head: 'Timeline Rules'!$A$40:$I$40
Name RC_Lane: 'Rate Card'!$A$5:$A$49
Name RC_Band: 'Rate Card'!$C$5:$C$49
Name RC_Transit: 'Rate Card'!$H$5:$H$49
Name SA_Lane: 'Schedule A'!$B$5:$B$145
Name SA_Date: 'Schedule A'!$J$5:$J$145
Name SA_Week: 'Schedule A'!$K$5:$K$145
Name SA_Chg: 'Schedule A'!$H$5:$H$145
Name SA_Kg: 'Schedule A'!$F$5:$F$145
Name SA_Meet: 'Schedule A'!$R$5:$R$145
Name SA_Late: 'Schedule A'!$S$5:$S$145
Name SA_Exp: 'Schedule A'!$Q$5:$Q$145
Name SB_Lane: 'Schedule B'!$B$5:$B$333
Name SB_Date: 'Schedule B'!$J$5:$J$333
Name SB_Week: 'Schedule B'!$K$5:$K$333
Name SB_Chg: 'Schedule B'!$H$5:$H$333
Name SB_Kg: 'Schedule B'!$F$5:$F$333
Name SB_Meet: 'Schedule B'!$R$5:$R$333
Name SB_Late: 'Schedule B'!$S$5:$S$333
Name SB_Exp: 'Schedule B'!$Q$5:$Q$333
Name RS_Lane: 'Optional Regional Stock'!$A$14:$A$22
Name RS_Flag: 'Optional Regional Stock'!$I$14:$I$22
Name RS_Transit: 'Optional Regional Stock'!$K$14:$K$22
Name RS_TotA: 'Optional Regional Stock'!$D$44
Name RS_TotB: 'Optional Regional Stock'!$E$44
Name RS_Loc: 'Optional Regional Stock'!$J$14:$J$22
Name RS_Rate: 'Optional Regional Stock'!$L$14:$L$22
Name RC_CostPS: 'Rate Card'!$P$5:$P$49
Name RC_Disc: 'Rate Card'!$N$5:$N$49
Name SA_From: 'Schedule A'!$U$5:$U$145
Name SA_Cost: 'Schedule A'!$Y$5:$Y$145
Name SA_M3: 'Schedule A'!$G$5:$G$145
Name SB_From: 'Schedule B'!$U$5:$U$333
Name SB_Cost: 'Schedule B'!$Y$5:$Y$333
Name SB_M3: 'Schedule B'!$G$5:$G$333
Name PP_provider_id: 'Provider Profile'!$B$6
Name PP_name: 'Provider Profile'!$B$7
Name PP_website: 'Provider Profile'!$B$8
Name PP_contact_name: 'Provider Profile'!$B$9
Name PP_contact_phone: 'Provider Profile'!$B$10
Name PP_contact_email: 'Provider Profile'!$B$11
Name PP_hq_country: 'Provider Profile'!$B$12
Name PP_quote_reference: 'Provider Profile'!$B$13
Name PP_quote_valid_until: 'Provider Profile'!$B$14
Name PP_response_date: 'Provider Profile'!$B$15
Name PP_currency: 'Provider Profile'!$B$16
Name EXPORT_TABLE: Export!$A$1:$D$737

Sheet Read Me
B1: Transport Volume Scenario: Request for Quotation
B2: FlexiTog EU B.V., Helmond, the Netherlands. Confidential. Shared for quotation purposes only, not for onward distribution.
B4: Contact name and e-mail | C4: [fill in before sending]
B5: Issue date | C5: [fill in before sending]
B6: Response deadline | C6: [fill in before sending]
B7: Rate validity requested | C7: [fill in before sending]
B9: Purpose | C9: FlexiTog EU requests rates and service information for shipments to nine destination countries, from its warehouse in Helmond or from a regional hub you propose. Your answers are compared on cost, reliability and quality.
B10: Origin | C10: Two possible origins. Default: the FlexiTog EU B.V. warehouse in Helmond, the Netherlands, with collection on working days. Alternative: your own hub or warehouse in the region, if you propose one. FlexiTog then stocks products there and directs supplier deliveries to it, and you deliver to the consignees from there (see Regional stock option). Pickup address and cut-off times are confirmed after selection.
B11: Destinations | C11: Nine lanes: Saudi Arabia, United Arab Emirates, Kuwait, Qatar, Türkiye, Morocco, Algeria, Egypt, Tunisia. Deliveries go to business addresses. Main delivery cities per lane are on the Volumes sheet. Deliveries to other cities in the same country follow your standard zone or remote-area pricing.
B12: Goods | C12: Cold-store workwear (jackets, trousers, coveralls, baselayers), gloves, footwear, headwear and small accessories in cartons. Occasional crated stainless steel cabinets of around 70 kg. Non-dangerous goods, no temperature control, stackable.
B13: Incoterm | C13: DAP, named consignee address (Incoterms 2020). FlexiTog EU pays transport to the door and export clearance in the Netherlands. The consignee clears import and pays import duty and VAT. Please state whether you offer import brokerage on the consignee's account and a DDP option per country.
B14: Service requirement | C14: Target door-to-door delivery after collection, in destination working days: GCC (Saudi Arabia, UAE, Kuwait, Qatar) 48 hours, next day preferred. Türkiye and Morocco 3 days. Tunisia and Egypt 4 days. Algeria 5 days. Please state your realistic transit time per lane and weight band. If a target needs local stock, please also complete the Optional Regional Stock sheet.
B15: Volume scenarios | C15: Two annual volume levels, Scenario A and Scenario B. Please quote both. Volumes are estimates for quotation and do not form a volume commitment.
B16: Volume basis | C16: One order equals one shipment. Weights and volumes are estimates. Chargeable kg uses the 1:6000 volumetric divisor. The peak month carries 1.5 times the average month.
... B23: Legend | C23: Yellow cells: your input. White cells: FlexiTog EU data or calculations, please leave unchanged.

Sheet Provider Profile
A1: Provider profile
A2: Please complete every yellow cell. Your company details, provider type, services, coverage per country and certifications.
A4: 1. Company details
A5: Field | B5: Your answer | C5: Note
A6: Provider ID (filled in by FlexiTog) | C6: Do not change
A7: Company name | C7: Required
A8: Website
A9: Contact person | C9: Person responsible for this quote
A10: Contact phone | C10: Include country code
A11: Contact e-mail
A12: Head office country
A13: Your quote reference
A14: Quote valid until | C14: Date
A15: Response date | C15: Date
A16: Quote currency | B16: EUR | C16: EUR, fixed
A19: 2. Provider type (all that apply)
A20: Type | B20: Yes / No | C20: Note
A21: Freight forwarder
A22: 3PL / contract logistics
A23: Carrier (own fleet)
A24: Courier / express
A25: Customs broker
A26: Distributor
A27: 4PL / lead logistics provider
A29: 3. Services offered
A30: Service | B30: Yes / No | C30: Note
A31: Road FTL
A32: Road groupage (LTL)
A33: Sea FCL
A34: Sea LCL
A35: Air freight
A36: Express / courier
A37: Export customs clearance (NL)
A38: Import customs brokerage
A39: DDP service
A40: Warehousing
A41: Cross-docking
A42: Last-mile delivery
... A51: 4. Coverage per destination
A52: Lane | B52: Country | C52: Region | D52: Presence | E52: Agent or partner name | F52: Import brokerage offered | G52: DDP offered
...

Sheet Volumes
A1: Annual volumes per lane
A2: Default origin: Helmond, NL. Lanes you choose to serve from your own regional hub use that hub as origin (Optional Regional Stock sheet). Estimates for quotation, not a volume commitment. Shipment-level dates are on the Schedule sheets.
A4: Scenario A
A5: Lane | B5: Destination country | C5: Main delivery cities | D5: Annual shipments | E5: Gross kg | F5: m3 | G5: Chargeable kg | H5: Avg kg per shipment | I5: Peak month shipments
A6: L01 | B6: Saudi Arabia | C6: Jeddah, Riyadh | D6: 50 | E6: 15486 | F6: 100.3 | G6: 16716 | H6: 310 | I6: ='Timeline Summary'!P6
A7: L02 | B7: United Arab Emirates | C7: Dubai | D7: 36 | E7: 1293 | F7: 8.4 | G7: 1395 | H7: 36 | I7: ='Timeline Summary'!P7
A8: L03 | B8: Kuwait | C8: Kuwait City | D8: 12 | E8: 3983 | F8: 25.8 | G8: 4300 | H8: 332 | I8: ='Timeline Summary'!P8
A9: L04 | B9: Qatar | C9: Doha | D9: 10 | E9: 343 | F9: 2.2 | G9: 371 | H9: 34 | I9: ='Timeline Summary'!P9
A10: L05 | B10: Türkiye | C10: Istanbul | D10: 16 | E10: 1819 | F10: 11.8 | G10: 1963 | H10: 114 | I10: ='Timeline Summary'!P10
A11: L06 | B11: Morocco | C11: Casablanca area, Rabat | D11: 6 | E11: 1278 | F11: 8.3 | G11: 1379 | H11: 213 | I11: ='Timeline Summary'!P11
A12: L07 | B12: Algeria | C12: Algiers | D12: 4 | E12: 328 | F12: 2.1 | G12: 354 | H12: 82 | I12: ='Timeline Summary'!P12
A13: L08 | B13: Egypt | C13: Cairo area | D13: 6 | E13: 1278 | F13: 8.3 | G13: 1379 | H13: 213 | I13: ='Timeline Summary'!P13
A14: L09 | B14: Tunisia | C14: Sousse | D14: 1 | E14: 8 | F14: 0.1 | G14: 8 | H14: 8 | I14: ='Timeline Summary'!P14
A15: Total | D15: =SUM(D6:D14) | E15: =SUM(E6:E14) | F15: =SUM(F6:F14) | G15: =SUM(G6:G14) | H15: =IFERROR(E15/D15,0) | I15: ='Timeline Summary'!P15
A18: Scenario B
A19: Lane | B19: Destination country | C19: Main delivery cities | D19: Annual shipments | E19: Gross kg | F19: m3 | G19: Chargeable kg | H19: Avg kg per shipment | I19: Peak month shipments
A20: L01 | B20: Saudi Arabia | C20: Jeddah, Riyadh | D20: 117 | E20: 37169 | F20: 240.7 | G20: 40121 | H20: 318 | I20: ='Timeline Summary'!P20
A21: L02 | B21: United Arab Emirates | C21: Dubai | D21: 84 | E21: 2932 | F21: 19 | G21: 3165 | H21: 35 | I21: ='Timeline Summary'!P21
A22: L03 | B22: Kuwait | C22: Kuwait City | D22: 29 | E22: 9698 | F22: 62.8 | G22: 10468 | H22: 334 | I22: ='Timeline Summary'!P22
A23: L04 | B23: Qatar | C23: Doha | D23: 23 | E23: 798 | F23: 5.2 | G23: 862 | H23: 35 | I23: ='Timeline Summary'!P23
A24: L05 | B24: Türkiye | C24: Istanbul | D24: 37 | E24: 4226 | F24: 27.4 | G24: 4562 | H24: 114 | I24: ='Timeline Summary'!P24
A25: L06 | B25: Morocco | C25: Casablanca area, Rabat | D25: 13 | E25: 1882 | F25: 12.2 | G25: 2032 | H25: 145 | I25: ='Timeline Summary'!P25
A26: L07 | B26: Algeria | C26: Algiers | D26: 9 | E26: 1554 | F26: 10.1 | G26: 1677 | H26: 173 | I26: ='Timeline Summary'!P26
A27: L08 | B27: Egypt | C27: Cairo area | D27: 13 | E27: 1882 | F27: 12.2 | G27: 2032 | H27: 145 | I27: ='Timeline Summary'!P27
A28: L09 | B28: Tunisia | C28: Sousse | D28: 4 | E28: 328 | F28: 2.1 | G28: 354 | H28: 82 | I28: ='Timeline Summary'!P28
A29: Total | D29: =SUM(D20:D28) | E29: =SUM(E20:E28) | F29: =SUM(F20:F28) | G29: =SUM(G20:G28) | H29: =IFERROR(E29/D29,0) | I29: ='Timeline Summary'!P29
A32: Annual shipments per weight band
A33: Lane | B33: Destination country | C33: Scenario A B1 0 to 30 kg | D33: Scenario A B2 30 to 100 kg | E33: Scenario A B3 100 to 500 kg | F33: Scenario A B4 500 to 2,000 kg | G33: Scenario A B5 over 2,000 kg | H33: Scenario B B1 0 to 30 kg | I33: Scenario B B2 30 to 100 kg | J33: Scenario B B3 100 to 500 kg | K33: Scenario B B4 500 to 2,000 kg | L33: Scenario B B5 over 2,000 kg
A34: L01 | B34: Saudi Arabia | C34: 22 | D34: 8 | E34: 10 | F34: 8 | G34: 2 | H34: 51 | I34: 19 | J34: 23 | K34: 19 | L34: 5
A35: L02 | B35: United Arab Emirates | C35: 32 | D35: 0 | E35: 4 | F35: 0 | G35: 0 | H35: 75 | I35: 0 | J35: 9 | K35: 0 | L35: 0
A36: L03 | B36: Kuwait | C36: 2 | D36: 0 | E36: 8 | F36: 2 | G36: 0 | H36: 5 | I36: 0 | J36: 19 | K36: 5 | L36: 0
A37: L04 | B37: Qatar | C37: 4 | D37: 6 | E37: 0 | F37: 0 | G37: 0 | H37: 9 | I37: 14 | J37: 0 | K37: 0 | L37: 0
A38: L05 | B38: Türkiye | C38: 6 | D38: 4 | E38: 6 | F38: 0 | G38: 0 | H38: 14 | I38: 9 | J38: 14 | K38: 0 | L38: 0
A39: L06 | B39: Morocco | C39: 3 | D39: 1 | E39: 1 | F39: 1 | G39: 0 | H39: 7 | I39: 2 | J39: 3 | K39: 1 | L39: 0
A40: L07 | B40: Algeria | C40: 2 | D40: 1 | E40: 1 | F40: 0 | G40: 0 | H40: 5 | I40: 1 | J40: 2 | K40: 1 | L40: 0
A41: L08 | B41: Egypt | C41: 3 | D41: 1 | E41: 1 | F41: 1 | G41: 0 | H41: 7 | I41: 2 | J41: 3 | K41: 1 | L41: 0
A42: L09 | B42: Tunisia | C42: 1 | D42: 0 | E42: 0 | F42: 0 | G42: 0 | H42: 2 | I42: 1 | J42: 1 | K42: 0 | L42: 0
A43: Total | C43: =SUM(C34:C42) | D43: =SUM(D34:D42) | E43: =SUM(E34:E42) | F43: =SUM(F34:F42) | G43: =SUM(G34:G42) | H43: =SUM(H34:H42) | I43: =SUM(I34:I42) | J43: =SUM(J34:J42) | ... L43: =SUM(L34:L42)
A46: Average shipment size per weight band
A47: Weight band | B47: Avg gross kg per shipment | C47: Avg chargeable kg per shipment | D47: Expected mode
...

Sheet Timeline Rules
A1: Timeline rules behind the shipment schedules
A2: Holiday dates for Islamic holidays are estimates and depend on moon sighting. Please correct any date you know to be different.
A4: Lane rules | K4: Monthly order profile (share of annual shipments)
A5: Lane | B5: Destination | C5: Destination weekend | D5: Weekend code (Excel) | E5: Target delivery (working days after pickup) | F5: Target | K5: Month | L5: Weight (1.0 = average month) | M5: Reason
A6: L01 | B6: Saudi Arabia | C6: Fri-Sat | D6: 7 | E6: 2 | F6: 48 hours, next day preferred | K6: 46388 | L6: 1 | M6: Normal month
A7: L02 | B7: United Arab Emirates | C7: Sat-Sun | D7: 1 | E7: 2 | F7: 48 hours, next day preferred | K7: 46419 | L7: 0.9 | M7: Ramadan starts (est. 8 Feb)
A8: L03 | B8: Kuwait | C8: Fri-Sat | D8: 7 | E8: 2 | F8: 48 hours, next day preferred | K8: 46447 | L8: 0.8 | M8: Ramadan and Eid al-Fitr (est. 9 to 11 Mar)
A9: L04 | B9: Qatar | C9: Fri-Sat | D9: 7 | E9: 2 | F9: 48 hours, next day preferred | K9: 46478 | L9: 1.1 | M9: Post-Ramadan restocking
A10: L05 | B10: Türkiye | C10: Sat-Sun | D10: 1 | E10: 3 | F10: 3 working days | K10: 46508 | L10: 0.9 | M10: Eid al-Adha (est. 15 to 18 May)
A11: L06 | B11: Morocco | C11: Sat-Sun | D11: 1 | E11: 3 | F11: 3 working days | K11: 46539 | L11: 1 | M11: Normal month
A12: L07 | B12: Algeria | C12: Fri-Sat | D12: 7 | E12: 5 | F12: 5 working days | K12: 46569 | L12: 0.8 | M12: Summer slowdown, GCC heat season
A13: L08 | B13: Egypt | C13: Fri-Sat | D13: 7 | E13: 4 | F13: 4 working days | K13: 46600 | L13: 0.8 | M13: Summer slowdown, European holidays
A14: L09 | B14: Tunisia | C14: Sat-Sun | D14: 1 | E14: 4 | F14: 4 working days | K14: 46631 | L14: 1.2 | M14: Season start, restocking
A15: GCC: priority market, next day preferred. Türkiye and Morocco: short routes, road or air. Tunisia and Egypt: longer clearance. Algeria: strictest import controls. | K15: 46661 | L15: 1.5 | M15: Peak month
A16: Order and pickup rules | K16: 46692 | L16: 1.2 | M16: Pre year-end orders
A17: Order release | B17: Orders are released on Helmond working days (Monday to Friday, excluding the Dutch holidays below). | K17: 46722 | L17: 0.8 | M17: Year-end holidays
A18: Planned pickup | B18: Same day as order release. Assumes release before your pickup cut-off. Please state your cut-off in question R3. | K18: Average | L18: =AVERAGE(L6:L17)
A19: Target delivery date | B19: Pickup date plus the target working days, counted in destination working days (skipping the destination weekend and holidays).
A20: Expected delivery date | B20: Pickup date plus your quoted transit days from the Rate Card, counted the same way. Overwrite per shipment in the yellow column where you know better.
A21: Weights | B21: Gross kg per shipment is an estimate. m3 = gross kg x 0.00648. Chargeable kg = gross kg x 1.0794 (1:6000 rule).
A22: Cartons | B22: Estimated with a 60 x 40 x 40 cm carton (0.096 m3).
A25: Helmond non-working days
A26: Date | B26: Holiday
A27: 46388 | B27: New Year's Day
A28: 46475 | B28: Easter Monday
A29: 46504 | B29: King's Day
A30: 46513 | B30: Ascension Day
A31: 46524 | B31: Whit Monday
A39: Destination non-delivery days (indicative, one column per lane)
A40: L01 Saudi Arabia | B40: L02 United Arab Emirates | C40: L03 Kuwait | D40: L04 Qatar | E40: L05 Türkiye | F40: L06 Morocco | G40: L07 Algeria | H40: L08 Egypt | I40: L09 Tunisia
A41: 46440 | B41: 46388 | C41: 46388 | D41: 46427 | E41: 46388 | F41: 46388 | G41: 46388 | H41: 46394 | I41: 46388
A42: 46455 | B42: 46455 | C42: 46443 | D42: 46455 | E42: 46455 | F42: 46398 | G42: 46399 | H42: 46412 | I42: 46401
A43: 46456 | B43: 46456 | C43: 46444 | D43: 46456 | E43: 46456 | F43: 46401 | G43: 46455 | H43: 46455 | I43: 46455
A44: 46457 | B44: 46457 | C44: 46455 | D44: 46457 | E44: 46457 | F44: 46455 | G44: 46456 | H44: 46456 | I44: 46456
A45: 46458 | B45: 46522 | C45: 46456 | D45: 46522 | E45: 46500 | F45: 46456 | G45: 46508 | H45: 46457 | I45: 46466
A46: 46522 | B46: 46523 | C46: 46457 | D46: 46523 | E46: 46508 | F46: 46508 | G46: 46523 | H46: 46502 | I46: 46486
A47: 46523 | B47: 46524 | C47: 46522 | D47: 46524 | E47: 46523 | F47: 46523 | G47: 46524 | H47: 46508 | I47: 46508
A48: 46524 | B48: 46525 | C48: 46523 | D48: 46525 | E48: 46524 | F48: 46524 | G48: 46544 | H48: 46510 | I48: 46523
A49: 46525 | B49: 46544 | C49: 46524 | D49: 46739 | E49: 46525 | F49: 46544 | G49: 46573 | H49: 46522 | I49: 46524
A50: 46653 | B50: 46613 | C50: 46525 | E50: 46526 | F50: 46598 | G50: 46613 | H50: 46523 | I50: 46544
...

Sheet Schedule A
A1: Scenario A: shipment schedule
A2: One row per shipment. Default origin is Helmond. Where another origin is possible or better (your hub W1 to W3, a supplier, another hub), set it per shipment in the yellow origin columns. Expected delivery and shipment cost then follow that origin.
A4: Shipment ID | B4: Lane | C4: Destination | D4: Delivery city | E4: Weight band | F4: Gross kg | G4: m3 (est.) | H4: Chargeable kg | I4: Cartons (est.) | J4: Order release date | K4: Week starting | L4: Planned pickup | M4: Target (working days) | N4: Target delivery date | O4: Quoted transit days | P4: Your expected delivery date (optional) | Q4: Expected delivery date | R4: Meets target | S4: Days late | T4: Comment | U4: Ships from | V4: Proposed origin (optional) | W4: Transit days from proposed origin (optional) | X4: Cost per shipment from proposed origin (EUR, optional) | Y4: Shipment cost (EUR)
A5: A-001 | B5: L04 | C5: Qatar | D5: Doha | E5: B1 0 to 30 kg | F5: 2.6 | G5: =F5*0.006477 | H5: =F5*1.079436 | I5: =MAX(1,ROUNDUP(G5/0.096,0)) | J5: 46391 | K5: =J5-WEEKDAY(J5,2)+1 | L5: =J5 | M5: =INDEX(LR_Target,MATCH(B5,LR_Lane,0)) | N5: =WORKDAY.INTL(L5,M5,INDEX(LR_Code,MATCH(B5,LR_Lane,0)),INDEX(DH_Table,0,MATCH(B5&"*",DH_Head,0))) | O5: =IF(W5<>"",W5,IF(U5="Helmond",IF(COUNTIFS(RC_Lane,B5,RC_Band,E5,RC_Transit,"<>")=0,"",SUMIFS(RC_Transit,RC_Lane,B5,RC_Band,E5)),IF(U5="Other","",IF(INDEX(RS_Transit,MATCH(B5,RS_Lane,0))="","",INDEX(RS_Transit,MATCH(B5,RS_Lane,0)))))) | Q5: =IF(P5<>"",P5,IF(O5="","",WORKDAY.INTL(L5,ROUNDUP(O5,0),INDEX(LR_Code,MATCH(B5,LR_Lane,0)),INDEX(DH_Table,0,MATCH(B5&"*",DH_Head,0))))) | R5: =IF(Q5="","",IF(Q5<=N5,"Yes","No")) | S5: =IF(Q5="","",IF(Q5<=N5,0,NETWORKDAYS.INTL(N5,Q5,INDEX(LR_Code,MATCH(B5,LR_Lane,0)),INDEX(DH_Table,0,MATCH(B5&"*",DH_Head,0)))-1)) | U5: =IF(V5<>"",V5,IF(IFERROR(INDEX(RS_Flag,MATCH(B5,RS_Lane,0)),"")="Yes",IF(IFERROR(INDEX(RS_Loc,MATCH(B5,RS_Lane,0)),"")="","Regional stock",IFERROR(INDEX(RS_Loc,MATCH(B5,RS_Lane,0)),"")),"Helmond")) | Y5: =IF(X5<>"",X5,IF(U5="Helmond",IF(COUNTIFS(RC_Lane,B5,RC_Band,E5,RC_CostPS,">0")=0,"",SUMIFS(RC_CostPS,RC_Lane,B5,RC_Band,E5)),IF(U5="Other","",IF(INDEX(RS_Rate,MATCH(B5,RS_Lane,0))="","",INDEX(RS_Rate,MATCH(B5,RS_Lane,0))))))
A6: A-002 | B6: L01 | C6: Saudi Arabia | D6: Riyadh | E6: B3 100 to 500 kg | F6: 279.6 | G6: =F6*0.006477 | H6: =F6*1.079436 | I6: =MAX(1,ROUNDUP(G6/0.096,0)) | J6: 46392 | K6: =J6-WEEKDAY(J6,2)+1 | L6: =J6 | M6: =INDEX(LR_Target,MATCH(B6,LR_Lane,0)) | N6: =WORKDAY.INTL(L6,M6,INDEX(LR_Code,MATCH(B6,LR_Lane,0)),INDEX(DH_Table,0,MATCH(B6&"*",DH_Head,0))) | O6: =IF(W6<>"",W6,IF(U6="Helmond",IF(COUNTIFS(RC_Lane,B6,RC_Band,E6,RC_Transit,"<>")=0,"",SUMIFS(RC_Transit,RC_Lane,B6,RC_Band,E6)),IF(U6="Other","",IF(INDEX(RS_Transit,MATCH(B6,RS_Lane,0))="","",INDEX(RS_Transit,MATCH(B6,RS_Lane,0)))))) | Q6: =IF(P6<>"",P6,IF(O6="","",WORKDAY.INTL(L6,ROUNDUP(O6,0),INDEX(LR_Code,MATCH(B6,LR_Lane,0)),INDEX(DH_Table,0,MATCH(B6&"*",DH_Head,0))))) | R6: =IF(Q6="","",IF(Q6<=N6,"Yes","No")) | S6: =IF(Q6="","",IF(Q6<=N6,0,NETWORKDAYS.INTL(N6,Q6,INDEX(LR_Code,MATCH(B6,LR_Lane,0)),INDEX(DH_Table,0,MATCH(B6&"*",DH_Head,0)))-1)) | U6: =IF(V6<>"",V6,IF(IFERROR(INDEX(RS_Flag,MATCH(B6,RS_Lane,0)),"")="Yes",IF(IFERROR(INDEX(RS_Loc,MATCH(B6,RS_Lane,0)),"")="","Regional stock",IFERROR(INDEX(RS_Loc,MATCH(B6,RS_Lane,0)),"")),"Helmond")) | Y6: =IF(X6<>"",X6,IF(U6="Helmond",IF(COUNTIFS(RC_Lane,B6,RC_Band,E6,RC_CostPS,">0")=0,"",SUMIFS(RC_CostPS,RC_Lane,B6,RC_Band,E6)),IF(U6="Other","",IF(INDEX(RS_Rate,MATCH(B6,RS_Lane,0))="","",INDEX(RS_Rate,MATCH(B6,RS_Lane,0))))))
A7: A-003 | B7: L01 | C7: Saudi Arabia | D7: Jeddah | E7: B1 0 to 30 kg | F7: 11.1 | G7: =F7*0.006477 | H7: =F7*1.079436 | I7: =MAX(1,ROUNDUP(G7/0.096,0)) | J7: 46395 | K7: =J7-WEEKDAY(J7,2)+1 | L7: =J7 | M7: =INDEX(LR_Target,MATCH(B7,LR_Lane,0)) | N7: =WORKDAY.INTL(L7,M7,INDEX(LR_Code,MATCH(B7,LR_Lane,0)),INDEX(DH_Table,0,MATCH(B7&"*",DH_Head,0))) | O7: =IF(W7<>"",W7,IF(U7="Helmond",IF(COUNTIFS(RC_Lane,B7,RC_Band,E7,RC_Transit,"<>")=0,"",SUMIFS(RC_Transit,RC_Lane,B7,RC_Band,E7)),IF(U7="Other","",IF(INDEX(RS_Transit,MATCH(B7,RS_Lane,0))="","",INDEX(RS_Transit,MATCH(B7,RS_Lane,0)))))) | Q7: =IF(P7<>"",P7,IF(O7="","",WORKDAY.INTL(L7,ROUNDUP(O7,0),INDEX(LR_Code,MATCH(B7,LR_Lane,0)),INDEX(DH_Table,0,MATCH(B7&"*",DH_Head,0))))) | R7: =IF(Q7="","",IF(Q7<=N7,"Yes","No")) | S7: =IF(Q7="","",IF(Q7<=N7,0,NETWORKDAYS.INTL(N7,Q7,INDEX(LR_Code,MATCH(B7,LR_Lane,0)),INDEX(DH_Table,0,MATCH(B7&"*",DH_Head,0)))-1)) | U7: =IF(V7<>"",V7,IF(IFERROR(INDEX(RS_Flag,MATCH(B7,RS_Lane,0)),"")="Yes",IF(IFERROR(INDEX(RS_Loc,MATCH(B7,RS_Lane,0)),"")="","Regional stock",IFERROR(INDEX(RS_Loc,MATCH(B7,RS_Lane,0)),"")),"Helmond")) | Y7: =IF(X7<>"",X7,IF(U7="Helmond",IF(COUNTIFS(RC_Lane,B7,RC_Band,E7,RC_CostPS,">0")=0,"",SUMIFS(RC_CostPS,RC_Lane,B7,RC_Band,E7)),IF(U7="Other","",IF(INDEX(RS_Rate,MATCH(B7,RS_Lane,0))="","",INDEX(RS_Rate,MATCH(B7,RS_Lane,0))))))
A8: A-004 | B8: L01 | C8: Saudi Arabia | D8: Riyadh | E8: B3 100 to 500 kg | F8: 270.6 | G8: =F8*0.006477 | H8: =F8*1.079436 | I8: =MAX(1,ROUNDUP(G8/0.096,0)) | J8: 46395 | K8: =J8-WEEKDAY(J8,2)+1 | L8: =J8 | M8: =INDEX(LR_Target,MATCH(B8,LR_Lane,0)) | N8: =WORKDAY.INTL(L8,M8,INDEX(LR_Code,MATCH(B8,LR_Lane,0)),INDEX(DH_Table,0,MATCH(B8&"*",DH_Head,0))) | O8: =IF(W8<>"",W8,IF(U8="Helmond",IF(COUNTIFS(RC_Lane,B8,RC_Band,E8,RC_Transit,"<>")=0,"",SUMIFS(RC_Transit,RC_Lane,B8,RC_Band,E8)),IF(U8="Other","",IF(INDEX(RS_Transit,MATCH(B8,RS_Lane,0))="","",INDEX(RS_Transit,MATCH(B8,RS_Lane,0)))))) | Q8: =IF(P8<>"",P8,IF(O8="","",WORKDAY.INTL(L8,ROUNDUP(O8,0),INDEX(LR_Code,MATCH(B8,LR_Lane,0)),INDEX(DH_Table,0,MATCH(B8&"*",DH_Head,0))))) | R8: =IF(Q8="","",IF(Q8<=N8,"Yes","No")) | S8: =IF(Q8="","",IF(Q8<=N8,0,NETWORKDAYS.INTL(N8,Q8,INDEX(LR_Code,MATCH(B8,LR_Lane,0)),INDEX(DH_Table,0,MATCH(B8&"*",DH_Head,0)))-1)) | U8: =IF(V8<>"",V8,IF(IFERROR(INDEX(RS_Flag,MATCH(B8,RS_Lane,0)),"")="Yes",IF(IFERROR(INDEX(RS_Loc,MATCH(B8,RS_Lane,0)),"")="","Regional stock",IFERROR(INDEX(RS_Loc,MATCH(B8,RS_Lane,0)),"")),"Helmond")) | Y8: =IF(X8<>"",X8,IF(U8="Helmond",IF(COUNTIFS(RC_Lane,B8,RC_Band,E8,RC_CostPS,">0")=0,"",SUMIFS(RC_CostPS,RC_Lane,B8,RC_Band,E8)),IF(U8="Other","",IF(INDEX(RS_Rate,MATCH(B8,RS_Lane,0))="","",INDEX(RS_Rate,MATCH(B8,RS_Lane,0))))))
A9: A-005 | B9: L02 | C9: United Arab Emirates | D9: Dubai | E9: B1 0 to 30 kg | F9: 10.9 | G9: =F9*0.006477 | H9: =F9*1.079436 | I9: =MAX(1,ROUNDUP(G9/0.096,0)) | J9: 46398 | K9: =J9-WEEKDAY(J9,2)+1 | L9: =J9 | M9: =INDEX(LR_Target,MATCH(B9,LR_Lane,0)) | N9: =WORKDAY.INTL(L9,M9,INDEX(LR_Code,MATCH(B9,LR_Lane,0)),INDEX(DH_Table,0,MATCH(B9&"*",DH_Head,0))) | O9: =IF(W9<>"",W9,IF(U9="Helmond",IF(COUNTIFS(RC_Lane,B9,RC_Band,E9,RC_Transit,"<>")=0,"",SUMIFS(RC_Transit,RC_Lane,B9,RC_Band,E9)),IF(U9="Other","",IF(INDEX(RS_Transit,MATCH(B9,RS_Lane,0))="","",INDEX(RS_Transit,MATCH(B9,RS_Lane,0)))))) | Q9: =IF(P9<>"",P9,IF(O9="","",WORKDAY.INTL(L9,ROUNDUP(O9,0),INDEX(LR_Code,MATCH(B9,LR_Lane,0)),INDEX(DH_Table,0,MATCH(B9&"*",DH_Head,0))))) | R9: =IF(Q9="","",IF(Q9<=N9,"Yes","No")) | S9: =IF(Q9="","",IF(Q9<=N9,0,NETWORKDAYS.INTL(N9,Q9,INDEX(LR_Code,MATCH(B9,LR_Lane,0)),INDEX(DH_Table,0,MATCH(B9&"*",DH_Head,0)))-1)) | U9: =IF(V9<>"",V9,IF(IFERROR(INDEX(RS_Flag,MATCH(B9,RS_Lane,0)),"")="Yes",IF(IFERROR(INDEX(RS_Loc,MATCH(B9,RS_Lane,0)),"")="","Regional stock",IFERROR(INDEX(RS_Loc,MATCH(B9,RS_Lane,0)),"")),"Helmond")) | Y9: =IF(X9<>"",X9,IF(U9="Helmond",IF(COUNTIFS(RC_Lane,B9,RC_Band,E9,RC_CostPS,">0")=0,"",SUMIFS(RC_CostPS,RC_Lane,B9,RC_Band,E9)),IF(U9="Other","",IF(INDEX(RS_Rate,MATCH(B9,RS_Lane,0))="","",INDEX(RS_Rate,MATCH(B9,RS_Lane,0))))))
A10: A-006 | B10: L02 | C10: United Arab Emirates | D10: Dubai | E10: B1 0 to 30 kg | F10: 14.1 | G10: =F10*0.006477 | H10: =F10*1.079436 | I10: =MAX(1,ROUNDUP(G10/0.096,0)) | J10: 46398 | K10: =J10-WEEKDAY(J10,2)+1 | L10: =J10 | M10: =INDEX(LR_Target,MATCH(B10,LR_Lane,0)) | N10: =WORKDAY.INTL(L10,M10,INDEX(LR_Code,MATCH(B10,LR_Lane,0)),INDEX(DH_Table,0,MATCH(B10&"*",DH_Head,0))) | O10: =IF(W10<>"",W10,IF(U10="Helmond",IF(COUNTIFS(RC_Lane,B10,RC_Band,E10,RC_Transit,"<>")=0,"",SUMIFS(RC_Transit,RC_Lane,B10,RC_Band,E10)),IF(U10="Other","",IF(INDEX(RS_Transit,MATCH(B10,RS_Lane,0))="","",INDEX(RS_Transit,MATCH(B10,RS_Lane,0)))))) | Q10: =IF(P10<>"",P10,IF(O10="","",WORKDAY.INTL(L10,ROUNDUP(O10,0),INDEX(LR_Code,MATCH(B10,LR_Lane,0)),INDEX(DH_Table,0,MATCH(B10&"*",DH_Head,0))))) | R10: =IF(Q10="","",IF(Q10<=N10,"Yes","No")) | S10: =IF(Q10="","",IF(Q10<=N10,0,NETWORKDAYS.INTL(N10,Q10,INDEX(LR_Code,MATCH(B10,LR_Lane,0)),INDEX(DH_Table,0,MATCH(B10&"*",DH_Head,0)))-1)) | U10: =IF(V10<>"",V10,IF(IFERROR(INDEX(RS_Flag,MATCH(B10,RS_Lane,0)),"")="Yes",IF(IFERROR(INDEX(RS_Loc,MATCH(B10,RS_Lane,0)),"")="","Regional stock",IFERROR(INDEX(RS_Loc,MATCH(B10,RS_Lane,0)),"")),"Helmond")) | Y10: =IF(X10<>"",X10,IF(U10="Helmond",IF(COUNTIFS(RC_Lane,B10,RC_Band,E10,RC_CostPS,">0")=0,"",SUMIFS(RC_CostPS,RC_Lane,B10,RC_Band,E10)),IF(U10="Other","",IF(INDEX(RS_Rate,MATCH(B10,RS_Lane,0))="","",INDEX(RS_Rate,MATCH(B10,RS_Lane,0))))))
A11: A-007 | B11: L05 | C11: Türkiye | D11: Istanbul | E11: B3 100 to 500 kg | F11: 376.7 | G11: =F11*0.006477 | H11: =F11*1.079436 | I11: =MAX(1,ROUNDUP(G11/0.096,0)) | J11: 46398 | K11: =J11-WEEKDAY(J11,2)+1 | L11: =J11 | M11: =INDEX(LR_Target,MATCH(B11,LR_Lane,0)) | N11: =WORKDAY.INTL(L11,M11,INDEX(LR_Code,MATCH(B11,LR_Lane,0)),INDEX(DH_Table,0,MATCH(B11&"*",DH_Head,0))) | O11: =IF(W11<>"",W11,IF(U11="Helmond",IF(COUNTIFS(RC_Lane,B11,RC_Band,E11,RC_Transit,"<>")=0,"",SUMIFS(RC_Transit,RC_Lane,B11,RC_Band,E11)),IF(U11="Other","",IF(INDEX(RS_Transit,MATCH(B11,RS_Lane,0))="","",INDEX(RS_Transit,MATCH(B11,RS_Lane,0)))))) | Q11: =IF(P11<>"",P11,IF(O11="","",WORKDAY.INTL(L11,ROUNDUP(O11,0),INDEX(LR_Code,MATCH(B11,LR_Lane,0)),INDEX(DH_Table,0,MATCH(B11&"*",DH_Head,0))))) | R11: =IF(Q11="","",IF(Q11<=N11,"Yes","No")) | S11: =IF(Q11="","",IF(Q11<=N11,0,NETWORKDAYS.INTL(N11,Q11,INDEX(LR_Code,MATCH(B11,LR_Lane,0)),INDEX(DH_Table,0,MATCH(B11&"*",DH_Head,0)))-1)) | U11: =IF(V11<>"",V11,IF(IFERROR(INDEX(RS_Flag,MATCH(B11,RS_Lane,0)),"")="Yes",IF(IFERROR(INDEX(RS_Loc,MATCH(B11,RS_Lane,0)),"")="","Regional stock",IFERROR(INDEX(RS_Loc,MATCH(B11,RS_Lane,0)),"")),"Helmond")) | Y11: =IF(X11<>"",X11,IF(U11="Helmond",IF(COUNTIFS(RC_Lane,B11,RC_Band,E11,RC_CostPS,">0")=0,"",SUMIFS(RC_CostPS,RC_Lane,B11,RC_Band,E11)),IF(U11="Other","",IF(INDEX(RS_Rate,MATCH(B11,RS_Lane,0))="","",INDEX(RS_Rate,MATCH(B11,RS_Lane,0))))))
A12: A-008 | B12: L06 | C12: Morocco | D12: Casablanca area | E12: B4 500 to 2,000 kg | F12: 941.5 | G12: =F12*0.006477 | H12: =F12*1.079436 | I12: =MAX(1,ROUNDUP(G12/0.096,0)) | J12: 46398 | K12: =J12-WEEKDAY(J12,2)+1 | L12: =J12 | M12: =INDEX(LR_Target,MATCH(B12,LR_Lane,0)) | N12: =WORKDAY.INTL(L12,M12,INDEX(LR_Code,MATCH(B12,LR_Lane,0)),INDEX(DH_Table,0,MATCH(B12&"*",DH_Head,0))) | O12: =IF(W12<>"",W12,IF(U12="Helmond",IF(COUNTIFS(RC_Lane,B12,RC_Band,E12,RC_Transit,"<>")=0,"",SUMIFS(RC_Transit,RC_Lane,B12,RC_Band,E12)),IF(U12="Other","",IF(INDEX(RS_Transit,MATCH(B12,RS_Lane,0))="","",INDEX(RS_Transit,MATCH(B12,RS_Lane,0)))))) | Q12: =IF(P12<>"",P12,IF(O12="","",WORKDAY.INTL(L12,ROUNDUP(O12,0),INDEX(LR_Code,MATCH(B12,LR_Lane,0)),INDEX(DH_Table,0,MATCH(B12&"*",DH_Head,0))))) | R12: =IF(Q12="","",IF(Q12<=N12,"Yes","No")) | S12: =IF(Q12="","",IF(Q12<=N12,0,NETWORKDAYS.INTL(N12,Q12,INDEX(LR_Code,MATCH(B12,LR_Lane,0)),INDEX(DH_Table,0,MATCH(B12&"*",DH_Head,0)))-1)) | U12: =IF(V12<>"",V12,IF(IFERROR(INDEX(RS_Flag,MATCH(B12,RS_Lane,0)),"")="Yes",IF(IFERROR(INDEX(RS_Loc,MATCH(B12,RS_Lane,0)),"")="","Regional stock",IFERROR(INDEX(RS_Loc,MATCH(B12,RS_Lane,0)),"")),"Helmond")) | Y12: =IF(X12<>"",X12,IF(U12="Helmond",IF(COUNTIFS(RC_Lane,B12,RC_Band,E12,RC_CostPS,">0")=0,"",SUMIFS(RC_CostPS,RC_Lane,B12,RC_Band,E12)),IF(U12="Other","",IF(INDEX(RS_Rate,MATCH(B12,RS_Lane,0))="","",INDEX(RS_Rate,MATCH(B12,RS_Lane,0))))))
A13: A-009 | B13: L01 | C13: Saudi Arabia | D13: Jeddah | E13: B1 0 to 30 kg | F13: 5.9 | G13: =F13*0.006477 | H13: =F13*1.079436 | I13: =MAX(1,ROUNDUP(G13/0.096,0)) | J13: 46400 | K13: =J13-WEEKDAY(J13,2)+1 | L13: =J13 | M13: =INDEX(LR_Target,MATCH(B13,LR_Lane,0)) | N13: =WORKDAY.INTL(L13,M13,INDEX(LR_Code,MATCH(B13,LR_Lane,0)),INDEX(DH_Table,0,MATCH(B13&"*",DH_Head,0))) | O13: =IF(W13<>"",W13,IF(U13="Helmond",IF(COUNTIFS(RC_Lane,B13,RC_Band,E13,RC_Transit,"<>")=0,"",SUMIFS(RC_Transit,RC_Lane,B13,RC_Band,E13)),IF(U13="Other","",IF(INDEX(RS_Transit,MATCH(B13,RS_Lane,0))="","",INDEX(RS_Transit,MATCH(B13,RS_Lane,0)))))) | Q13: =IF(P13<>"",P13,IF(O13="","",WORKDAY.INTL(L13,ROUNDUP(O13,0),INDEX(LR_Code,MATCH(B13,LR_Lane,0)),INDEX(DH_Table,0,MATCH(B13&"*",DH_Head,0))))) | R13: =IF(Q13="","",IF(Q13<=N13,"Yes","No")) | S13: =IF(Q13="","",IF(Q13<=N13,0,NETWORKDAYS.INTL(N13,Q13,INDEX(LR_Code,MATCH(B13,LR_Lane,0)),INDEX(DH_Table,0,MATCH(B13&"*",DH_Head,0)))-1)) | U13: =IF(V13<>"",V13,IF(IFERROR(INDEX(RS_Flag,MATCH(B13,RS_Lane,0)),"")="Yes",IF(IFERROR(INDEX(RS_Loc,MATCH(B13,RS_Lane,0)),"")="","Regional stock",IFERROR(INDEX(RS_Loc,MATCH(B13,RS_Lane,0)),"")),"Helmond")) | Y13: =IF(X13<>"",X13,IF(U13="Helmond",IF(COUNTIFS(RC_Lane,B13,RC_Band,E13,RC_CostPS,">0")=0,"",SUMIFS(RC_CostPS,RC_Lane,B13,RC_Band,E13)),IF(U13="Other","",IF(INDEX(RS_Rate,MATCH(B13,RS_Lane,0))="","",INDEX(RS_Rate,MATCH(B13,RS_Lane,0))))))
A14: A-010 | B14: L03 | C14: Kuwait | D14: Kuwait City | E14: B4 500 to 2,000 kg | F14: 1093 | G14: =F14*0.006477 | H14: =F14*1.079436 | I14: =MAX(1,ROUNDUP(G14/0.096,0)) | J14: 46407 | K14: =J14-WEEKDAY(J14,2)+1 | L14: =J14 | M14: =INDEX(LR_Target,MATCH(B14,LR_Lane,0)) | N14: =WORKDAY.INTL(L14,M14,INDEX(LR_Code,MATCH(B14,LR_Lane,0)),INDEX(DH_Table,0,MATCH(B14&"*",DH_Head,0))) | O14: =IF(W14<>"",W14,IF(U14="Helmond",IF(COUNTIFS(RC_Lane,B14,RC_Band,E14,RC_Transit,"<>")=0,"",SUMIFS(RC_Transit,RC_Lane,B14,RC_Band,E14)),IF(U14="Other","",IF(INDEX(RS_Transit,MATCH(B14,RS_Lane,0))="","",INDEX(RS_Transit,MATCH(B14,RS_Lane,0)))))) | Q14: =IF(P14<>"",P14,IF(O14="","",WORKDAY.INTL(L14,ROUNDUP(O14,0),INDEX(LR_Code,MATCH(B14,LR_Lane,0)),INDEX(DH_Table,0,MATCH(B14&"*",DH_Head,0))))) | R14: =IF(Q14="","",IF(Q14<=N14,"Yes","No")) | S14: =IF(Q14="","",IF(Q14<=N14,0,NETWORKDAYS.INTL(N14,Q14,INDEX(LR_Code,MATCH(B14,LR_Lane,0)),INDEX(DH_Table,0,MATCH(B14&"*",DH_Head,0)))-1)) | U14: =IF(V14<>"",V14,IF(IFERROR(INDEX(RS_Flag,MATCH(B14,RS_Lane,0)),"")="Yes",IF(IFERROR(INDEX(RS_Loc,MATCH(B14,RS_Lane,0)),"")="","Regional stock",IFERROR(INDEX(RS_Loc,MATCH(B14,RS_Lane,0)),"")),"Helmond")) | Y14: =IF(X14<>"",X14,IF(U14="Helmond",IF(COUNTIFS(RC_Lane,B14,RC_Band,E14,RC_CostPS,">0")=0,"",SUMIFS(RC_CostPS,RC_Lane,B14,RC_Band,E14)),IF(U14="Other","",IF(INDEX(RS_Rate,MATCH(B14,RS_Lane,0))="","",INDEX(RS_Rate,MATCH(B14,RS_Lane,0))))))
A15: A-011 | B15: L01 | C15: Saudi Arabia | D15: Jeddah | E15: B3 100 to 500 kg | F15: 232.3 | G15: =F15*0.006477 | H15: =F15*1.079436 | I15: =MAX(1,ROUNDUP(G15/0.096,0)) | J15: 46413 | K15: =J15-WEEKDAY(J15,2)+1 | L15: =J15 | M15: =INDEX(LR_Target,MATCH(B15,LR_Lane,0)) | N15: =WORKDAY.INTL(L15,M15,INDEX(LR_Code,MATCH(B15,LR_Lane,0)),INDEX(DH_Table,0,MATCH(B15&"*",DH_Head,0))) | O15: =IF(W15<>"",W15,IF(U15="Helmond",IF(COUNTIFS(RC_Lane,B15,RC_Band,E15,RC_Transit,"<>")=0,"",SUMIFS(RC_Transit,RC_Lane,B15,RC_Band,E15)),IF(U15="Other","",IF(INDEX(RS_Transit,MATCH(B15,RS_Lane,0))="","",INDEX(RS_Transit,MATCH(B15,RS_Lane,0)))))) | Q15: =IF(P15<>"",P15,IF(O15="","",WORKDAY.INTL(L15,ROUNDUP(O15,0),INDEX(LR_Code,MATCH(B15,LR_Lane,0)),INDEX(DH_Table,0,MATCH(B15&"*",DH_Head,0))))) | R15: =IF(Q15="","",IF(Q15<=N15,"Yes","No")) | S15: =IF(Q15="","",IF(Q15<=N15,0,NETWORKDAYS.INTL(N15,Q15,INDEX(LR_Code,MATCH(B15,LR_Lane,0)),INDEX(DH_Table,0,MATCH(B15&"*",DH_Head,0)))-1)) | U15: =IF(V15<>"",V15,IF(IFERROR(INDEX(RS_Flag,MATCH(B15,RS_Lane,0)),"")="Yes",IF(IFERROR(INDEX(RS_Loc,MATCH(B15,RS_Lane,0)),"")="","Regional stock",IFERROR(INDEX(RS_Loc,MATCH(B15,RS_Lane,0)),"")),"Helmond")) | Y15: =IF(X15<>"",X15,IF(U15="Helmond",IF(COUNTIFS(RC_Lane,B15,RC_Band,E15,RC_CostPS,">0")=0,"",SUMIFS(RC_CostPS,RC_Lane,B15,RC_Band,E15)),IF(U15="Other","",IF(INDEX(RS_Rate,MATCH(B15,RS_Lane,0))="","",INDEX(RS_Rate,MATCH(B15,RS_Lane,0))))))
A16: A-012 | B16: L02 | C16: United Arab Emirates | D16: Dubai | E16: B3 100 to 500 kg | F16: 202.1 | G16: =F16*0.006477 | H16: =F16*1.079436 | I16: =MAX(1,ROUNDUP(G16/0.096,0)) | J16: 46413 | K16: =J16-WEEKDAY(J16,2)+1 | L16: =J16 | M16: =INDEX(LR_Target,MATCH(B16,LR_Lane,0)) | N16: =WORKDAY.INTL(L16,M16,INDEX(LR_Code,MATCH(B16,LR_Lane,0)),INDEX(DH_Table,0,MATCH(B16&"*",DH_Head,0))) | O16: =IF(W16<>"",W16,IF(U16="Helmond",IF(COUNTIFS(RC_Lane,B16,RC_Band,E16,RC_Transit,"<>")=0,"",SUMIFS(RC_Transit,RC_Lane,B16,RC_Band,E16)),IF(U16="Other","",IF(INDEX(RS_Transit,MATCH(B16,RS_Lane,0))="","",INDEX(RS_Transit,MATCH(B16,RS_Lane,0)))))) | Q16: =IF(P16<>"",P16,IF(O16="","",WORKDAY.INTL(L16,ROUNDUP(O16,0),INDEX(LR_Code,MATCH(B16,LR_Lane,0)),INDEX(DH_Table,0,MATCH(B16&"*",DH_Head,0))))) | R16: =IF(Q16="","",IF(Q16<=N16,"Yes","No")) | S16: =IF(Q16="","",IF(Q16<=N16,0,NETWORKDAYS.INTL(N16,Q16,INDEX(LR_Code,MATCH(B16,LR_Lane,0)),INDEX(DH_Table,0,MATCH(B16&"*",DH_Head,0)))-1)) | U16: =IF(V16<>"",V16,IF(IFERROR(INDEX(RS_Flag,MATCH(B16,RS_Lane,0)),"")="Yes",IF(IFERROR(INDEX(RS_Loc,MATCH(B16,RS_Lane,0)),"")="","Regional stock",IFERROR(INDEX(RS_Loc,MATCH(B16,RS_Lane,0)),"")),"Helmond")) | Y16: =IF(X16<>"",X16,IF(U16="Helmond",IF(COUNTIFS(RC_Lane,B16,RC_Band,E16,RC_CostPS,">0")=0,"",SUMIFS(RC_CostPS,RC_Lane,B16,RC_Band,E16)),IF(U16="Other","",IF(INDEX(RS_Rate,MATCH(B16,RS_Lane,0))="","",INDEX(RS_Rate,MATCH(B16,RS_Lane,0))))))
... A145: A-141 | B145: L01 | C145: Saudi Arabia | D145: Riyadh | E145: B1 0 to 30 kg | F145: 9.5 | G145: =F145*0.006477 | H145: =F145*1.079436 | I145: =MAX(1,ROUNDUP(G145/0.096,0)) | J145: 46750 | K145: =J145-WEEKDAY(J145,2)+1 | L145: =J145 | M145: =INDEX(LR_Target,MATCH(B145,LR_Lane,0)) | N145: =WORKDAY.INTL(L145,M145,INDEX(LR_Code,MATCH(B145,LR_Lane,0)),INDEX(DH_Table,0,MATCH(B145&"*",DH_Head,0))) | O145: =IF(W145<>"",W145,IF(U145="Helmond",IF(COUNTIFS(RC_Lane,B145,RC_Band,E145,RC_Transit,"<>")=0,"",SUMIFS(RC_Transit,RC_Lane,B145,RC_Band,E145)),IF(U145="Other","",IF(INDEX(RS_Transit,MATCH(B145,RS_Lane,0))="","",INDEX(RS_Transit,MATCH(B145,RS_Lane,0)))))) | Q145: =IF(P145<>"",P145,IF(O145="","",WORKDAY.INTL(L145,ROUNDUP(O145,0),INDEX(LR_Code,MATCH(B145,LR_Lane,0)),INDEX(DH_Table,0,MATCH(B145&"*",DH_Head,0))))) | R145: =IF(Q145="","",IF(Q145<=N145,"Yes","No")) | S145: =IF(Q145="","",IF(Q145<=N145,0,NETWORKDAYS.INTL(N145,Q145,INDEX(LR_Code,MATCH(B145,LR_Lane,0)),INDEX(DH_Table,0,MATCH(B145&"*",DH_Head,0)))-1)) | U145: =IF(V145<>"",V145,IF(IFERROR(INDEX(RS_Flag,MATCH(B145,RS_Lane,0)),"")="Yes",IF(IFERROR(INDEX(RS_Loc,MATCH(B145,RS_Lane,0)),"")="","Regional stock",IFERROR(INDEX(RS_Loc,MATCH(B145,RS_Lane,0)),"")),"Helmond")) | Y145: =IF(X145<>"",X145,IF(U145="Helmond",IF(COUNTIFS(RC_Lane,B145,RC_Band,E145,RC_CostPS,">0")=0,"",SUMIFS(RC_CostPS,RC_Lane,B145,RC_Band,E145)),IF(U145="Other","",IF(INDEX(RS_Rate,MATCH(B145,RS_Lane,0))="","",INDEX(RS_Rate,MATCH(B145,RS_Lane,0))))))
A146: =COUNTA(A5:A145)&" shipments" | F146: =SUM(F5:F145) | G146: =SUM(G5:G145) | H146: =SUM(H5:H145) | I146: =SUM(I5:I145) | U146: =COUNTIF(U5:U145,"<>Helmond")&" not from Helmond" | Y146: =SUM(Y5:Y145)

Sheet Schedule B
A1: Scenario B: shipment schedule
A2: One row per shipment. Default origin is Helmond. Where another origin is possible or better (your hub W1 to W3, a supplier, another hub), set it per shipment in the yellow origin columns. Expected delivery and shipment cost then follow that origin.
A4: Shipment ID | B4: Lane | C4: Destination | D4: Delivery city | E4: Weight band | F4: Gross kg | G4: m3 (est.) | H4: Chargeable kg | I4: Cartons (est.) | J4: Order release date | K4: Week starting | L4: Planned pickup | M4: Target (working days) | N4: Target delivery date | O4: Quoted transit days | P4: Your expected delivery date (optional) | Q4: Expected delivery date | R4: Meets target | S4: Days late | T4: Comment | U4: Ships from | V4: Proposed origin (optional) | W4: Transit days from proposed origin (optional) | X4: Cost per shipment from proposed origin (EUR, optional) | Y4: Shipment cost (EUR)
A5: B-001 | B5: L02 | C5: United Arab Emirates | D5: Dubai | E5: B1 0 to 30 kg | F5: 7.7 | G5: =F5*0.006477 | H5: =F5*1.079436 | I5: =MAX(1,ROUNDUP(G5/0.096,0)) | J5: 46391 | K5: =J5-WEEKDAY(J5,2)+1 | L5: =J5 | M5: =INDEX(LR_Target,MATCH(B5,LR_Lane,0)) | N5: =WORKDAY.INTL(L5,M5,INDEX(LR_Code,MATCH(B5,LR_Lane,0)),INDEX(DH_Table,0,MATCH(B5&"*",DH_Head,0))) | O5: =IF(W5<>"",W5,IF(U5="Helmond",IF(COUNTIFS(RC_Lane,B5,RC_Band,E5,RC_Transit,"<>")=0,"",SUMIFS(RC_Transit,RC_Lane,B5,RC_Band,E5)),IF(U5="Other","",IF(INDEX(RS_Transit,MATCH(B5,RS_Lane,0))="","",INDEX(RS_Transit,MATCH(B5,RS_Lane,0)))))) | Q5: =IF(P5<>"",P5,IF(O5="","",WORKDAY.INTL(L5,ROUNDUP(O5,0),INDEX(LR_Code,MATCH(B5,LR_Lane,0)),INDEX(DH_Table,0,MATCH(B5&"*",DH_Head,0))))) | R5: =IF(Q5="","",IF(Q5<=N5,"Yes","No")) | S5: =IF(Q5="","",IF(Q5<=N5,0,NETWORKDAYS.INTL(N5,Q5,INDEX(LR_Code,MATCH(B5,LR_Lane,0)),INDEX(DH_Table,0,MATCH(B5&"*",DH_Head,0)))-1)) | U5: =IF(V5<>"",V5,IF(IFERROR(INDEX(RS_Flag,MATCH(B5,RS_Lane,0)),"")="Yes",IF(IFERROR(INDEX(RS_Loc,MATCH(B5,RS_Lane,0)),"")="","Regional stock",IFERROR(INDEX(RS_Loc,MATCH(B5,RS_Lane,0)),"")),"Helmond")) | Y5: =IF(X5<>"",X5,IF(U5="Helmond",IF(COUNTIFS(RC_Lane,B5,RC_Band,E5,RC_CostPS,">0")=0,"",SUMIFS(RC_CostPS,RC_Lane,B5,RC_Band,E5)*(1-SUMIFS(RC_Disc,RC_Lane,B5,RC_Band,E5))),IF(U5="Other","",IF(INDEX(RS_Rate,MATCH(B5,RS_Lane,0))="","",INDEX(RS_Rate,MATCH(B5,RS_Lane,0))))))
A6: B-002 | B6: L05 | C6: Türkiye | D6: Istanbul | E6: B1 0 to 30 kg | F6: 3.5 | G6: =F6*0.006477 | H6: =F6*1.079436 | I6: =MAX(1,ROUNDUP(G6/0.096,0)) | J6: 46391 | K6: =J6-WEEKDAY(J6,2)+1 | L6: =J6 | M6: =INDEX(LR_Target,MATCH(B6,LR_Lane,0)) | N6: =WORKDAY.INTL(L6,M6,INDEX(LR_Code,MATCH(B6,LR_Lane,0)),INDEX(DH_Table,0,MATCH(B6&"*",DH_Head,0))) | O6: =IF(W6<>"",W6,IF(U6="Helmond",IF(COUNTIFS(RC_Lane,B6,RC_Band,E6,RC_Transit,"<>")=0,"",SUMIFS(RC_Transit,RC_Lane,B6,RC_Band,E6)),IF(U6="Other","",IF(INDEX(RS_Transit,MATCH(B6,RS_Lane,0))="","",INDEX(RS_Transit,MATCH(B6,RS_Lane,0)))))) | Q6: =IF(P6<>"",P6,IF(O6="","",WORKDAY.INTL(L6,ROUNDUP(O6,0),INDEX(LR_Code,MATCH(B6,LR_Lane,0)),INDEX(DH_Table,0,MATCH(B6&"*",DH_Head,0))))) | R6: =IF(Q6="","",IF(Q6<=N6,"Yes","No")) | S6: =IF(Q6="","",IF(Q6<=N6,0,NETWORKDAYS.INTL(N6,Q6,INDEX(LR_Code,MATCH(B6,LR_Lane,0)),INDEX(DH_Table,0,MATCH(B6&"*",DH_Head,0)))-1)) | U6: =IF(V6<>"",V6,IF(IFERROR(INDEX(RS_Flag,MATCH(B6,RS_Lane,0)),"")="Yes",IF(IFERROR(INDEX(RS_Loc,MATCH(B6,RS_Lane,0)),"")="","Regional stock",IFERROR(INDEX(RS_Loc,MATCH(B6,RS_Lane,0)),"")),"Helmond")) | Y6: =IF(X6<>"",X6,IF(U6="Helmond",IF(COUNTIFS(RC_Lane,B6,RC_Band,E6,RC_CostPS,">0")=0,"",SUMIFS(RC_CostPS,RC_Lane,B6,RC_Band,E6)*(1-SUMIFS(RC_Disc,RC_Lane,B6,RC_Band,E6))),IF(U6="Other","",IF(INDEX(RS_Rate,MATCH(B6,RS_Lane,0))="","",INDEX(RS_Rate,MATCH(B6,RS_Lane,0))))))
A7: B-003 | B7: L01 | C7: Saudi Arabia | D7: Riyadh | E7: B3 100 to 500 kg | F7: 153.3 | G7: =F7*0.006477 | H7: =F7*1.079436 | I7: =MAX(1,ROUNDUP(G7/0.096,0)) | J7: 46393 | K7: =J7-WEEKDAY(J7,2)+1 | L7: =J7 | M7: =INDEX(LR_Target,MATCH(B7,LR_Lane,0)) | N7: =WORKDAY.INTL(L7,M7,INDEX(LR_Code,MATCH(B7,LR_Lane,0)),INDEX(DH_Table,0,MATCH(B7&"*",DH_Head,0))) | O7: =IF(W7<>"",W7,IF(U7="Helmond",IF(COUNTIFS(RC_Lane,B7,RC_Band,E7,RC_Transit,"<>")=0,"",SUMIFS(RC_Transit,RC_Lane,B7,RC_Band,E7)),IF(U7="Other","",IF(INDEX(RS_Transit,MATCH(B7,RS_Lane,0))="","",INDEX(RS_Transit,MATCH(B7,RS_Lane,0)))))) | Q7: =IF(P7<>"",P7,IF(O7="","",WORKDAY.INTL(L7,ROUNDUP(O7,0),INDEX(LR_Code,MATCH(B7,LR_Lane,0)),INDEX(DH_Table,0,MATCH(B7&"*",DH_Head,0))))) | R7: =IF(Q7="","",IF(Q7<=N7,"Yes","No")) | S7: =IF(Q7="","",IF(Q7<=N7,0,NETWORKDAYS.INTL(N7,Q7,INDEX(LR_Code,MATCH(B7,LR_Lane,0)),INDEX(DH_Table,0,MATCH(B7&"*",DH_Head,0)))-1)) | U7: =IF(V7<>"",V7,IF(IFERROR(INDEX(RS_Flag,MATCH(B7,RS_Lane,0)),"")="Yes",IF(IFERROR(INDEX(RS_Loc,MATCH(B7,RS_Lane,0)),"")="","Regional stock",IFERROR(INDEX(RS_Loc,MATCH(B7,RS_Lane,0)),"")),"Helmond")) | Y7: =IF(X7<>"",X7,IF(U7="Helmond",IF(COUNTIFS(RC_Lane,B7,RC_Band,E7,RC_CostPS,">0")=0,"",SUMIFS(RC_CostPS,RC_Lane,B7,RC_Band,E7)*(1-SUMIFS(RC_Disc,RC_Lane,B7,RC_Band,E7))),IF(U7="Other","",IF(INDEX(RS_Rate,MATCH(B7,RS_Lane,0))="","",INDEX(RS_Rate,MATCH(B7,RS_Lane,0))))))
A8: B-004 | B8: L05 | C8: Türkiye | D8: Istanbul | E8: B1 0 to 30 kg | F8: 2.2 | G8: =F8*0.006477 | H8: =F8*1.079436 | I8: =MAX(1,ROUNDUP(G8/0.096,0)) | J8: 46393 | K8: =J8-WEEKDAY(J8,2)+1 | L8: =J8 | M8: =INDEX(LR_Target,MATCH(B8,LR_Lane,0)) | N8: =WORKDAY.INTL(L8,M8,INDEX(LR_Code,MATCH(B8,LR_Lane,0)),INDEX(DH_Table,0,MATCH(B8&"*",DH_Head,0))) | O8: =IF(W8<>"",W8,IF(U8="Helmond",IF(COUNTIFS(RC_Lane,B8,RC_Band,E8,RC_Transit,"<>")=0,"",SUMIFS(RC_Transit,RC_Lane,B8,RC_Band,E8)),IF(U8="Other","",IF(INDEX(RS_Transit,MATCH(B8,RS_Lane,0))="","",INDEX(RS_Transit,MATCH(B8,RS_Lane,0)))))) | Q8: =IF(P8<>"",P8,IF(O8="","",WORKDAY.INTL(L8,ROUNDUP(O8,0),INDEX(LR_Code,MATCH(B8,LR_Lane,0)),INDEX(DH_Table,0,MATCH(B8&"*",DH_Head,0))))) | R8: =IF(Q8="","",IF(Q8<=N8,"Yes","No")) | S8: =IF(Q8="","",IF(Q8<=N8,0,NETWORKDAYS.INTL(N8,Q8,INDEX(LR_Code,MATCH(B8,LR_Lane,0)),INDEX(DH_Table,0,MATCH(B8&"*",DH_Head,0)))-1)) | U8: =IF(V8<>"",V8,IF(IFERROR(INDEX(RS_Flag,MATCH(B8,RS_Lane,0)),"")="Yes",IF(IFERROR(INDEX(RS_Loc,MATCH(B8,RS_Lane,0)),"")="","Regional stock",IFERROR(INDEX(RS_Loc,MATCH(B8,RS_Lane,0)),"")),"Helmond")) | Y8: =IF(X8<>"",X8,IF(U8="Helmond",IF(COUNTIFS(RC_Lane,B8,RC_Band,E8,RC_CostPS,">0")=0,"",SUMIFS(RC_CostPS,RC_Lane,B8,RC_Band,E8)*(1-SUMIFS(RC_Disc,RC_Lane,B8,RC_Band,E8))),IF(U8="Other","",IF(INDEX(RS_Rate,MATCH(B8,RS_Lane,0))="","",INDEX(RS_Rate,MATCH(B8,RS_Lane,0))))))
A9: B-005 | B9: L01 | C9: Saudi Arabia | D9: Jeddah | E9: B1 0 to 30 kg | F9: 10.9 | G9: =F9*0.006477 | H9: =F9*1.079436 | I9: =MAX(1,ROUNDUP(G9/0.096,0)) | J9: 46395 | K9: =J9-WEEKDAY(J9,2)+1 | L9: =J9 | M9: =INDEX(LR_Target,MATCH(B9,LR_Lane,0)) | N9: =WORKDAY.INTL(L9,M9,INDEX(LR_Code,MATCH(B9,LR_Lane,0)),INDEX(DH_Table,0,MATCH(B9&"*",DH_Head,0))) | O9: =IF(W9<>"",W9,IF(U9="Helmond",IF(COUNTIFS(RC_Lane,B9,RC_Band,E9,RC_Transit,"<>")=0,"",SUMIFS(RC_Transit,RC_Lane,B9,RC_Band,E9)),IF(U9="Other","",IF(INDEX(RS_Transit,MATCH(B9,RS_Lane,0))="","",INDEX(RS_Transit,MATCH(B9,RS_Lane,0)))))) | Q9: =IF(P9<>"",P9,IF(O9="","",WORKDAY.INTL(L9,ROUNDUP(O9,0),INDEX(LR_Code,MATCH(B9,LR_Lane,0)),INDEX(DH_Table,0,MATCH(B9&"*",DH_Head,0))))) | R9: =IF(Q9="","",IF(Q9<=N9,"Yes","No")) | S9: =IF(Q9="","",IF(Q9<=N9,0,NETWORKDAYS.INTL(N9,Q9,INDEX(LR_Code,MATCH(B9,LR_Lane,0)),INDEX(DH_Table,0,MATCH(B9&"*",DH_Head,0)))-1)) | U9: =IF(V9<>"",V9,IF(IFERROR(INDEX(RS_Flag,MATCH(B9,RS_Lane,0)),"")="Yes",IF(IFERROR(INDEX(RS_Loc,MATCH(B9,RS_Lane,0)),"")="","Regional stock",IFERROR(INDEX(RS_Loc,MATCH(B9,RS_Lane,0)),"")),"Helmond")) | Y9: =IF(X9<>"",X9,IF(U9="Helmond",IF(COUNTIFS(RC_Lane,B9,RC_Band,E9,RC_CostPS,">0")=0,"",SUMIFS(RC_CostPS,RC_Lane,B9,RC_Band,E9)*(1-SUMIFS(RC_Disc,RC_Lane,B9,RC_Band,E9))),IF(U9="Other","",IF(INDEX(RS_Rate,MATCH(B9,RS_Lane,0))="","",INDEX(RS_Rate,MATCH(B9,RS_Lane,0))))))
A10: B-006 | B10: L02 | C10: United Arab Emirates | D10: Dubai | E10: B1 0 to 30 kg | F10: 7.4 | G10: =F10*0.006477 | H10: =F10*1.079436 | I10: =MAX(1,ROUNDUP(G10/0.096,0)) | J10: 46399 | K10: =J10-WEEKDAY(J10,2)+1 | L10: =J10 | M10: =INDEX(LR_Target,MATCH(B10,LR_Lane,0)) | N10: =WORKDAY.INTL(L10,M10,INDEX(LR_Code,MATCH(B10,LR_Lane,0)),INDEX(DH_Table,0,MATCH(B10&"*",DH_Head,0))) | O10: =IF(W10<>"",W10,IF(U10="Helmond",IF(COUNTIFS(RC_Lane,B10,RC_Band,E10,RC_Transit,"<>")=0,"",SUMIFS(RC_Transit,RC_Lane,B10,RC_Band,E10)),IF(U10="Other","",IF(INDEX(RS_Transit,MATCH(B10,RS_Lane,0))="","",INDEX(RS_Transit,MATCH(B10,RS_Lane,0)))))) | Q10: =IF(P10<>"",P10,IF(O10="","",WORKDAY.INTL(L10,ROUNDUP(O10,0),INDEX(LR_Code,MATCH(B10,LR_Lane,0)),INDEX(DH_Table,0,MATCH(B10&"*",DH_Head,0))))) | R10: =IF(Q10="","",IF(Q10<=N10,"Yes","No")) | S10: =IF(Q10="","",IF(Q10<=N10,0,NETWORKDAYS.INTL(N10,Q10,INDEX(LR_Code,MATCH(B10,LR_Lane,0)),INDEX(DH_Table,0,MATCH(B10&"*",DH_Head,0)))-1)) | U10: =IF(V10<>"",V10,IF(IFERROR(INDEX(RS_Flag,MATCH(B10,RS_Lane,0)),"")="Yes",IF(IFERROR(INDEX(RS_Loc,MATCH(B10,RS_Lane,0)),"")="","Regional stock",IFERROR(INDEX(RS_Loc,MATCH(B10,RS_Lane,0)),"")),"Helmond")) | Y10: =IF(X10<>"",X10,IF(U10="Helmond",IF(COUNTIFS(RC_Lane,B10,RC_Band,E10,RC_CostPS,">0")=0,"",SUMIFS(RC_CostPS,RC_Lane,B10,RC_Band,E10)*(1-SUMIFS(RC_Disc,RC_Lane,B10,RC_Band,E10))),IF(U10="Other","",IF(INDEX(RS_Rate,MATCH(B10,RS_Lane,0))="","",INDEX(RS_Rate,MATCH(B10,RS_Lane,0))))))
A11: B-007 | B11: L02 | C11: United Arab Emirates | D11: Dubai | E11: B1 0 to 30 kg | F11: 11 | G11: =F11*0.006477 | H11: =F11*1.079436 | I11: =MAX(1,ROUNDUP(G11/0.096,0)) | J11: 46399 | K11: =J11-WEEKDAY(J11,2)+1 | L11: =J11 | M11: =INDEX(LR_Target,MATCH(B11,LR_Lane,0)) | N11: =WORKDAY.INTL(L11,M11,INDEX(LR_Code,MATCH(B11,LR_Lane,0)),INDEX(DH_Table,0,MATCH(B11&"*",DH_Head,0))) | O11: =IF(W11<>"",W11,IF(U11="Helmond",IF(COUNTIFS(RC_Lane,B11,RC_Band,E11,RC_Transit,"<>")=0,"",SUMIFS(RC_Transit,RC_Lane,B11,RC_Band,E11)),IF(U11="Other","",IF(INDEX(RS_Transit,MATCH(B11,RS_Lane,0))="","",INDEX(RS_Transit,MATCH(B11,RS_Lane,0)))))) | Q11: =IF(P11<>"",P11,IF(O11="","",WORKDAY.INTL(L11,ROUNDUP(O11,0),INDEX(LR_Code,MATCH(B11,LR_Lane,0)),INDEX(DH_Table,0,MATCH(B11&"*",DH_Head,0))))) | R11: =IF(Q11="","",IF(Q11<=N11,"Yes","No")) | S11: =IF(Q11="","",IF(Q11<=N11,0,NETWORKDAYS.INTL(N11,Q11,INDEX(LR_Code,MATCH(B11,LR_Lane,0)),INDEX(DH_Table,0,MATCH(B11&"*",DH_Head,0)))-1)) | U11: =IF(V11<>"",V11,IF(IFERROR(INDEX(RS_Flag,MATCH(B11,RS_Lane,0)),"")="Yes",IF(IFERROR(INDEX(RS_Loc,MATCH(B11,RS_Lane,0)),"")="","Regional stock",IFERROR(INDEX(RS_Loc,MATCH(B11,RS_Lane,0)),"")),"Helmond")) | Y11: =IF(X11<>"",X11,IF(U11="Helmond",IF(COUNTIFS(RC_Lane,B11,RC_Band,E11,RC_CostPS,">0")=0,"",SUMIFS(RC_CostPS,RC_Lane,B11,RC_Band,E11)*(1-SUMIFS(RC_Disc,RC_Lane,B11,RC_Band,E11))),IF(U11="Other","",IF(INDEX(RS_Rate,MATCH(B11,RS_Lane,0))="","",INDEX(RS_Rate,MATCH(B11,RS_Lane,0))))))
A12: B-008 | B12: L03 | C12: Kuwait | D12: Kuwait City | E12: B1 0 to 30 kg | F12: 4.8 | G12: =F12*0.006477 | H12: =F12*1.079436 | I12: =MAX(1,ROUNDUP(G12/0.096,0)) | J12: 46399 | K12: =J12-WEEKDAY(J12,2)+1 | L12: =J12 | M12: =INDEX(LR_Target,MATCH(B12,LR_Lane,0)) | N12: =WORKDAY.INTL(L12,M12,INDEX(LR_Code,MATCH(B12,LR_Lane,0)),INDEX(DH_Table,0,MATCH(B12&"*",DH_Head,0))) | O12: =IF(W12<>"",W12,IF(U12="Helmond",IF(COUNTIFS(RC_Lane,B12,RC_Band,E12,RC_Transit,"<>")=0,"",SUMIFS(RC_Transit,RC_Lane,B12,RC_Band,E12)),IF(U12="Other","",IF(INDEX(RS_Transit,MATCH(B12,RS_Lane,0))="","",INDEX(RS_Transit,MATCH(B12,RS_Lane,0)))))) | Q12: =IF(P12<>"",P12,IF(O12="","",WORKDAY.INTL(L12,ROUNDUP(O12,0),INDEX(LR_Code,MATCH(B12,LR_Lane,0)),INDEX(DH_Table,0,MATCH(B12&"*",DH_Head,0))))) | R12: =IF(Q12="","",IF(Q12<=N12,"Yes","No")) | S12: =IF(Q12="","",IF(Q12<=N12,0,NETWORKDAYS.INTL(N12,Q12,INDEX(LR_Code,MATCH(B12,LR_Lane,0)),INDEX(DH_Table,0,MATCH(B12&"*",DH_Head,0)))-1)) | U12: =IF(V12<>"",V12,IF(IFERROR(INDEX(RS_Flag,MATCH(B12,RS_Lane,0)),"")="Yes",IF(IFERROR(INDEX(RS_Loc,MATCH(B12,RS_Lane,0)),"")="","Regional stock",IFERROR(INDEX(RS_Loc,MATCH(B12,RS_Lane,0)),"")),"Helmond")) | Y12: =IF(X12<>"",X12,IF(U12="Helmond",IF(COUNTIFS(RC_Lane,B12,RC_Band,E12,RC_CostPS,">0")=0,"",SUMIFS(RC_CostPS,RC_Lane,B12,RC_Band,E12)*(1-SUMIFS(RC_Disc,RC_Lane,B12,RC_Band,E12))),IF(U12="Other","",IF(INDEX(RS_Rate,MATCH(B12,RS_Lane,0))="","",INDEX(RS_Rate,MATCH(B12,RS_Lane,0))))))
A13: B-009 | B13: L01 | C13: Saudi Arabia | D13: Riyadh | E13: B1 0 to 30 kg | F13: 9.4 | G13: =F13*0.006477 | H13: =F13*1.079436 | I13: =MAX(1,ROUNDUP(G13/0.096,0)) | J13: 46400 | K13: =J13-WEEKDAY(J13,2)+1 | L13: =J13 | M13: =INDEX(LR_Target,MATCH(B13,LR_Lane,0)) | N13: =WORKDAY.INTL(L13,M13,INDEX(LR_Code,MATCH(B13,LR_Lane,0)),INDEX(DH_Table,0,MATCH(B13&"*",DH_Head,0))) | O13: =IF(W13<>"",W13,IF(U13="Helmond",IF(COUNTIFS(RC_Lane,B13,RC_Band,E13,RC_Transit,"<>")=0,"",SUMIFS(RC_Transit,RC_Lane,B13,RC_Band,E13)),IF(U13="Other","",IF(INDEX(RS_Transit,MATCH(B13,RS_Lane,0))="","",INDEX(RS_Transit,MATCH(B13,RS_Lane,0)))))) | Q13: =IF(P13<>"",P13,IF(O13="","",WORKDAY.INTL(L13,ROUNDUP(O13,0),INDEX(LR_Code,MATCH(B13,LR_Lane,0)),INDEX(DH_Table,0,MATCH(B13&"*",DH_Head,0))))) | R13: =IF(Q13="","",IF(Q13<=N13,"Yes","No")) | S13: =IF(Q13="","",IF(Q13<=N13,0,NETWORKDAYS.INTL(N13,Q13,INDEX(LR_Code,MATCH(B13,LR_Lane,0)),INDEX(DH_Table,0,MATCH(B13&"*",DH_Head,0)))-1)) | U13: =IF(V13<>"",V13,IF(IFERROR(INDEX(RS_Flag,MATCH(B13,RS_Lane,0)),"")="Yes",IF(IFERROR(INDEX(RS_Loc,MATCH(B13,RS_Lane,0)),"")="","Regional stock",IFERROR(INDEX(RS_Loc,MATCH(B13,RS_Lane,0)),"")),"Helmond")) | Y13: =IF(X13<>"",X13,IF(U13="Helmond",IF(COUNTIFS(RC_Lane,B13,RC_Band,E13,RC_CostPS,">0")=0,"",SUMIFS(RC_CostPS,RC_Lane,B13,RC_Band,E13)*(1-SUMIFS(RC_Disc,RC_Lane,B13,RC_Band,E13))),IF(U13="Other","",IF(INDEX(RS_Rate,MATCH(B13,RS_Lane,0))="","",INDEX(RS_Rate,MATCH(B13,RS_Lane,0))))))
A14: B-010 | B14: L02 | C14: United Arab Emirates | D14: Dubai | E14: B1 0 to 30 kg | F14: 3.2 | G14: =F14*0.006477 | H14: =F14*1.079436 | I14: =MAX(1,ROUNDUP(G14/0.096,0)) | J14: 46400 | K14: =J14-WEEKDAY(J14,2)+1 | L14: =J14 | M14: =INDEX(LR_Target,MATCH(B14,LR_Lane,0)) | N14: =WORKDAY.INTL(L14,M14,INDEX(LR_Code,MATCH(B14,LR_Lane,0)),INDEX(DH_Table,0,MATCH(B14&"*",DH_Head,0))) | O14: =IF(W14<>"",W14,IF(U14="Helmond",IF(COUNTIFS(RC_Lane,B14,RC_Band,E14,RC_Transit,"<>")=0,"",SUMIFS(RC_Transit,RC_Lane,B14,RC_Band,E14)),IF(U14="Other","",IF(INDEX(RS_Transit,MATCH(B14,RS_Lane,0))="","",INDEX(RS_Transit,MATCH(B14,RS_Lane,0)))))) | Q14: =IF(P14<>"",P14,IF(O14="","",WORKDAY.INTL(L14,ROUNDUP(O14,0),INDEX(LR_Code,MATCH(B14,LR_Lane,0)),INDEX(DH_Table,0,MATCH(B14&"*",DH_Head,0))))) | R14: =IF(Q14="","",IF(Q14<=N14,"Yes","No")) | S14: =IF(Q14="","",IF(Q14<=N14,0,NETWORKDAYS.INTL(N14,Q14,INDEX(LR_Code,MATCH(B14,LR_Lane,0)),INDEX(DH_Table,0,MATCH(B14&"*",DH_Head,0)))-1)) | U14: =IF(V14<>"",V14,IF(IFERROR(INDEX(RS_Flag,MATCH(B14,RS_Lane,0)),"")="Yes",IF(IFERROR(INDEX(RS_Loc,MATCH(B14,RS_Lane,0)),"")="","Regional stock",IFERROR(INDEX(RS_Loc,MATCH(B14,RS_Lane,0)),"")),"Helmond")) | Y14: =IF(X14<>"",X14,IF(U14="Helmond",IF(COUNTIFS(RC_Lane,B14,RC_Band,E14,RC_CostPS,">0")=0,"",SUMIFS(RC_CostPS,RC_Lane,B14,RC_Band,E14)*(1-SUMIFS(RC_Disc,RC_Lane,B14,RC_Band,E14))),IF(U14="Other","",IF(INDEX(RS_Rate,MATCH(B14,RS_Lane,0))="","",INDEX(RS_Rate,MATCH(B14,RS_Lane,0))))))
A15: B-011 | B15: L04 | C15: Qatar | D15: Doha | E15: B2 30 to 100 kg | F15: 68.9 | G15: =F15*0.006477 | H15: =F15*1.079436 | I15: =MAX(1,ROUNDUP(G15/0.096,0)) | J15: 46400 | K15: =J15-WEEKDAY(J15,2)+1 | L15: =J15 | M15: =INDEX(LR_Target,MATCH(B15,LR_Lane,0)) | N15: =WORKDAY.INTL(L15,M15,INDEX(LR_Code,MATCH(B15,LR_Lane,0)),INDEX(DH_Table,0,MATCH(B15&"*",DH_Head,0))) | O15: =IF(W15<>"",W15,IF(U15="Helmond",IF(COUNTIFS(RC_Lane,B15,RC_Band,E15,RC_Transit,"<>")=0,"",SUMIFS(RC_Transit,RC_Lane,B15,RC_Band,E15)),IF(U15="Other","",IF(INDEX(RS_Transit,MATCH(B15,RS_Lane,0))="","",INDEX(RS_Transit,MATCH(B15,RS_Lane,0)))))) | Q15: =IF(P15<>"",P15,IF(O15="","",WORKDAY.INTL(L15,ROUNDUP(O15,0),INDEX(LR_Code,MATCH(B15,LR_Lane,0)),INDEX(DH_Table,0,MATCH(B15&"*",DH_Head,0))))) | R15: =IF(Q15="","",IF(Q15<=N15,"Yes","No")) | S15: =IF(Q15="","",IF(Q15<=N15,0,NETWORKDAYS.INTL(N15,Q15,INDEX(LR_Code,MATCH(B15,LR_Lane,0)),INDEX(DH_Table,0,MATCH(B15&"*",DH_Head,0)))-1)) | U15: =IF(V15<>"",V15,IF(IFERROR(INDEX(RS_Flag,MATCH(B15,RS_Lane,0)),"")="Yes",IF(IFERROR(INDEX(RS_Loc,MATCH(B15,RS_Lane,0)),"")="","Regional stock",IFERROR(INDEX(RS_Loc,MATCH(B15,RS_Lane,0)),"")),"Helmond")) | Y15: =IF(X15<>"",X15,IF(U15="Helmond",IF(COUNTIFS(RC_Lane,B15,RC_Band,E15,RC_CostPS,">0")=0,"",SUMIFS(RC_CostPS,RC_Lane,B15,RC_Band,E15)*(1-SUMIFS(RC_Disc,RC_Lane,B15,RC_Band,E15))),IF(U15="Other","",IF(INDEX(RS_Rate,MATCH(B15,RS_Lane,0))="","",INDEX(RS_Rate,MATCH(B15,RS_Lane,0))))))
A16: B-012 | B16: L01 | C16: Saudi Arabia | D16: Riyadh | E16: B1 0 to 30 kg | F16: 13.8 | G16: =F16*0.006477 | H16: =F16*1.079436 | I16: =MAX(1,ROUNDUP(G16/0.096,0)) | J16: 46401 | K16: =J16-WEEKDAY(J16,2)+1 | L16: =J16 | M16: =INDEX(LR_Target,MATCH(B16,LR_Lane,0)) | N16: =WORKDAY.INTL(L16,M16,INDEX(LR_Code,MATCH(B16,LR_Lane,0)),INDEX(DH_Table,0,MATCH(B16&"*",DH_Head,0))) | O16: =IF(W16<>"",W16,IF(U16="Helmond",IF(COUNTIFS(RC_Lane,B16,RC_Band,E16,RC_Transit,"<>")=0,"",SUMIFS(RC_Transit,RC_Lane,B16,RC_Band,E16)),IF(U16="Other","",IF(INDEX(RS_Transit,MATCH(B16,RS_Lane,0))="","",INDEX(RS_Transit,MATCH(B16,RS_Lane,0)))))) | Q16: =IF(P16<>"",P16,IF(O16="","",WORKDAY.INTL(L16,ROUNDUP(O16,0),INDEX(LR_Code,MATCH(B16,LR_Lane,0)),INDEX(DH_Table,0,MATCH(B16&"*",DH_Head,0))))) | R16: =IF(Q16="","",IF(Q16<=N16,"Yes","No")) | S16: =IF(Q16="","",IF(Q16<=N16,0,NETWORKDAYS.INTL(N16,Q16,INDEX(LR_Code,MATCH(B16,LR_Lane,0)),INDEX(DH_Table,0,MATCH(B16&"*",DH_Head,0)))-1)) | U16: =IF(V16<>"",V16,IF(IFERROR(INDEX(RS_Flag,MATCH(B16,RS_Lane,0)),"")="Yes",IF(IFERROR(INDEX(RS_Loc,MATCH(B16,RS_Lane,0)),"")="","Regional stock",IFERROR(INDEX(RS_Loc,MATCH(B16,RS_Lane,0)),"")),"Helmond")) | Y16: =IF(X16<>"",X16,IF(U16="Helmond",IF(COUNTIFS(RC_Lane,B16,RC_Band,E16,RC_CostPS,">0")=0,"",SUMIFS(RC_CostPS,RC_Lane,B16,RC_Band,E16)*(1-SUMIFS(RC_Disc,RC_Lane,B16,RC_Band,E16))),IF(U16="Other","",IF(INDEX(RS_Rate,MATCH(B16,RS_Lane,0))="","",INDEX(RS_Rate,MATCH(B16,RS_Lane,0))))))
... A333: B-329 | B333: L06 | C333: Morocco | D333: Casablanca area | E333: B4 500 to 2,000 kg | F333: 941.5 | G333: =F333*0.006477 | H333: =F333*1.079436 | I333: =MAX(1,ROUNDUP(G333/0.096,0)) | J333: 46752 | K333: =J333-WEEKDAY(J333,2)+1 | L333: =J333 | M333: =INDEX(LR_Target,MATCH(B333,LR_Lane,0)) | N333: =WORKDAY.INTL(L333,M333,INDEX(LR_Code,MATCH(B333,LR_Lane,0)),INDEX(DH_Table,0,MATCH(B333&"*",DH_Head,0))) | O333: =IF(W333<>"",W333,IF(U333="Helmond",IF(COUNTIFS(RC_Lane,B333,RC_Band,E333,RC_Transit,"<>")=0,"",SUMIFS(RC_Transit,RC_Lane,B333,RC_Band,E333)),IF(U333="Other","",IF(INDEX(RS_Transit,MATCH(B333,RS_Lane,0))="","",INDEX(RS_Transit,MATCH(B333,RS_Lane,0)))))) | Q333: =IF(P333<>"",P333,IF(O333="","",WORKDAY.INTL(L333,ROUNDUP(O333,0),INDEX(LR_Code,MATCH(B333,LR_Lane,0)),INDEX(DH_Table,0,MATCH(B333&"*",DH_Head,0))))) | R333: =IF(Q333="","",IF(Q333<=N333,"Yes","No")) | S333: =IF(Q333="","",IF(Q333<=N333,0,NETWORKDAYS.INTL(N333,Q333,INDEX(LR_Code,MATCH(B333,LR_Lane,0)),INDEX(DH_Table,0,MATCH(B333&"*",DH_Head,0)))-1)) | U333: =IF(V333<>"",V333,IF(IFERROR(INDEX(RS_Flag,MATCH(B333,RS_Lane,0)),"")="Yes",IF(IFERROR(INDEX(RS_Loc,MATCH(B333,RS_Lane,0)),"")="","Regional stock",IFERROR(INDEX(RS_Loc,MATCH(B333,RS_Lane,0)),"")),"Helmond")) | Y333: =IF(X333<>"",X333,IF(U333="Helmond",IF(COUNTIFS(RC_Lane,B333,RC_Band,E333,RC_CostPS,">0")=0,"",SUMIFS(RC_CostPS,RC_Lane,B333,RC_Band,E333)*(1-SUMIFS(RC_Disc,RC_Lane,B333,RC_Band,E333))),IF(U333="Other","",IF(INDEX(RS_Rate,MATCH(B333,RS_Lane,0))="","",INDEX(RS_Rate,MATCH(B333,RS_Lane,0))))))
A334: =COUNTA(A5:A333)&" shipments" | F334: =SUM(F5:F333) | G334: =SUM(G5:G333) | H334: =SUM(H5:H333) | I334: =SUM(I5:I333) | U334: =COUNTIF(U5:U333,"<>Helmond")&" not from Helmond" | Y334: =SUM(Y5:Y333)

Sheet Timeline Summary
A1: Timeline summary: shipments per month and week, and on-time check
A2: Counts come from the two schedule sheets. The on-time check fills in once transit days are on the Rate Card.
A4: Scenario A: shipments per month
A5: Lane | B5: Destination | C5: Jan | D5: Feb | E5: Mar | F5: Apr | G5: May | H5: Jun | I5: Jul | J5: Aug | K5: Sep | L5: Oct | M5: Nov | N5: Dec | O5: Year | P5: Peak month
A6: L01 | B6: Saudi Arabia | C6: =COUNTIFS(SA_Lane,$A6,SA_Date,">="&DATE(2027,1,1),SA_Date,"<"&DATE(2027,2,1)) | D6: =COUNTIFS(SA_Lane,$A6,SA_Date,">="&DATE(2027,2,1),SA_Date,"<"&DATE(2027,3,1)) | E6: =COUNTIFS(SA_Lane,$A6,SA_Date,">="&DATE(2027,3,1),SA_Date,"<"&DATE(2027,4,1)) | F6: =COUNTIFS(SA_Lane,$A6,SA_Date,">="&DATE(2027,4,1),SA_Date,"<"&DATE(2027,5,1)) | G6: =COUNTIFS(SA_Lane,$A6,SA_Date,">="&DATE(2027,5,1),SA_Date,"<"&DATE(2027,6,1)) | H6: =COUNTIFS(SA_Lane,$A6,SA_Date,">="&DATE(2027,6,1),SA_Date,"<"&DATE(2027,7,1)) | I6: =COUNTIFS(SA_Lane,$A6,SA_Date,">="&DATE(2027,7,1),SA_Date,"<"&DATE(2027,8,1)) | J6: =COUNTIFS(SA_Lane,$A6,SA_Date,">="&DATE(2027,8,1),SA_Date,"<"&DATE(2027,9,1)) | K6: =COUNTIFS(SA_Lane,$A6,SA_Date,">="&DATE(2027,9,1),SA_Date,"<"&DATE(2027,10,1)) | L6: =COUNTIFS(SA_Lane,$A6,SA_Date,">="&DATE(2027,10,1),SA_Date,"<"&DATE(2027,11,1)) | M6: =COUNTIFS(SA_Lane,$A6,SA_Date,">="&DATE(2027,11,1),SA_Date,"<"&DATE(2027,12,1)) | N6: =COUNTIFS(SA_Lane,$A6,SA_Date,">="&DATE(2027,12,1),SA_Date,"<"&DATE(2028,1,1)) | O6: =SUM(C6:N6) | P6: =MAX(C6:N6)
A7: L02 | B7: United Arab Emirates | C7: =COUNTIFS(SA_Lane,$A7,SA_Date,">="&DATE(2027,1,1),SA_Date,"<"&DATE(2027,2,1)) | D7: =COUNTIFS(SA_Lane,$A7,SA_Date,">="&DATE(2027,2,1),SA_Date,"<"&DATE(2027,3,1)) | E7: =COUNTIFS(SA_Lane,$A7,SA_Date,">="&DATE(2027,3,1),SA_Date,"<"&DATE(2027,4,1)) | F7: =COUNTIFS(SA_Lane,$A7,SA_Date,">="&DATE(2027,4,1),SA_Date,"<"&DATE(2027,5,1)) | G7: =COUNTIFS(SA_Lane,$A7,SA_Date,">="&DATE(2027,5,1),SA_Date,"<"&DATE(2027,6,1)) | H7: =COUNTIFS(SA_Lane,$A7,SA_Date,">="&DATE(2027,6,1),SA_Date,"<"&DATE(2027,7,1)) | I7: =COUNTIFS(SA_Lane,$A7,SA_Date,">="&DATE(2027,7,1),SA_Date,"<"&DATE(2027,8,1)) | J7: =COUNTIFS(SA_Lane,$A7,SA_Date,">="&DATE(2027,8,1),SA_Date,"<"&DATE(2027,9,1)) | K7: =COUNTIFS(SA_Lane,$A7,SA_Date,">="&DATE(2027,9,1),SA_Date,"<"&DATE(2027,10,1)) | L7: =COUNTIFS(SA_Lane,$A7,SA_Date,">="&DATE(2027,10,1),SA_Date,"<"&DATE(2027,11,1)) | M7: =COUNTIFS(SA_Lane,$A7,SA_Date,">="&DATE(2027,11,1),SA_Date,"<"&DATE(2027,12,1)) | N7: =COUNTIFS(SA_Lane,$A7,SA_Date,">="&DATE(2027,12,1),SA_Date,"<"&DATE(2028,1,1)) | O7: =SUM(C7:N7) | P7: =MAX(C7:N7)
A8: L03 | B8: Kuwait | C8: =COUNTIFS(SA_Lane,$A8,SA_Date,">="&DATE(2027,1,1),SA_Date,"<"&DATE(2027,2,1)) | D8: =COUNTIFS(SA_Lane,$A8,SA_Date,">="&DATE(2027,2,1),SA_Date,"<"&DATE(2027,3,1)) | E8: =COUNTIFS(SA_Lane,$A8,SA_Date,">="&DATE(2027,3,1),SA_Date,"<"&DATE(2027,4,1)) | F8: =COUNTIFS(SA_Lane,$A8,SA_Date,">="&DATE(2027,4,1),SA_Date,"<"&DATE(2027,5,1)) | G8: =COUNTIFS(SA_Lane,$A8,SA_Date,">="&DATE(2027,5,1),SA_Date,"<"&DATE(2027,6,1)) | H8: =COUNTIFS(SA_Lane,$A8,SA_Date,">="&DATE(2027,6,1),SA_Date,"<"&DATE(2027,7,1)) | I8: =COUNTIFS(SA_Lane,$A8,SA_Date,">="&DATE(2027,7,1),SA_Date,"<"&DATE(2027,8,1)) | J8: =COUNTIFS(SA_Lane,$A8,SA_Date,">="&DATE(2027,8,1),SA_Date,"<"&DATE(2027,9,1)) | K8: =COUNTIFS(SA_Lane,$A8,SA_Date,">="&DATE(2027,9,1),SA_Date,"<"&DATE(2027,10,1)) | L8: =COUNTIFS(SA_Lane,$A8,SA_Date,">="&DATE(2027,10,1),SA_Date,"<"&DATE(2027,11,1)) | M8: =COUNTIFS(SA_Lane,$A8,SA_Date,">="&DATE(2027,11,1),SA_Date,"<"&DATE(2027,12,1)) | N8: =COUNTIFS(SA_Lane,$A8,SA_Date,">="&DATE(2027,12,1),SA_Date,"<"&DATE(2028,1,1)) | O8: =SUM(C8:N8) | P8: =MAX(C8:N8)
A9: L04 | B9: Qatar | C9: =COUNTIFS(SA_Lane,$A9,SA_Date,">="&DATE(2027,1,1),SA_Date,"<"&DATE(2027,2,1)) | D9: =COUNTIFS(SA_Lane,$A9,SA_Date,">="&DATE(2027,2,1),SA_Date,"<"&DATE(2027,3,1)) | E9: =COUNTIFS(SA_Lane,$A9,SA_Date,">="&DATE(2027,3,1),SA_Date,"<"&DATE(2027,4,1)) | F9: =COUNTIFS(SA_Lane,$A9,SA_Date,">="&DATE(2027,4,1),SA_Date,"<"&DATE(2027,5,1)) | G9: =COUNTIFS(SA_Lane,$A9,SA_Date,">="&DATE(2027,5,1),SA_Date,"<"&DATE(2027,6,1)) | H9: =COUNTIFS(SA_Lane,$A9,SA_Date,">="&DATE(2027,6,1),SA_Date,"<"&DATE(2027,7,1)) | I9: =COUNTIFS(SA_Lane,$A9,SA_Date,">="&DATE(2027,7,1),SA_Date,"<"&DATE(2027,8,1)) | J9: =COUNTIFS(SA_Lane,$A9,SA_Date,">="&DATE(2027,8,1),SA_Date,"<"&DATE(2027,9,1)) | K9: =COUNTIFS(SA_Lane,$A9,SA_Date,">="&DATE(2027,9,1),SA_Date,"<"&DATE(2027,10,1)) | L9: =COUNTIFS(SA_Lane,$A9,SA_Date,">="&DATE(2027,10,1),SA_Date,"<"&DATE(2027,11,1)) | M9: =COUNTIFS(SA_Lane,$A9,SA_Date,">="&DATE(2027,11,1),SA_Date,"<"&DATE(2027,12,1)) | N9: =COUNTIFS(SA_Lane,$A9,SA_Date,">="&DATE(2027,12,1),SA_Date,"<"&DATE(2028,1,1)) | O9: =SUM(C9:N9) | P9: =MAX(C9:N9)
